Workbook

Sheet 目次・前提
A1: 採用のウラ側 ブログ改善レポート
A2: 作成日：2026-10-10 対象：https://saiyo-ura.com/ 作成：GSC・ASPデータ分析
A4: シート一覧
A5: サマリー | B5: 結論・主要指標・仮説の検証結果・最優先の対応
A6: 良い点・悪い点 | B6: 現状のブログの強みと弱み（根拠データと対策つき）
A7: 今後の方向性 | B7: ポジショニング・注力テーマ・やめること・新規記事案・ロードマップ・KPI
A8: 全記事_修正点 | B8: 全139記事の修正点を優先順に一覧化（診断・カニバリ・SEO・タイトル・導線・推奨案件）
A9: 重点9記事_詳細 | B9: 最優先9記事のアクションプラン（分析・カニバリ・タイトル案・導線の位置とマイクロコピー）
A10: カニバリ分析 | B10: 記事グループごとの競合判定・根拠・解消案、複数記事に該当するクエリ
A11: URL・技術課題 | B11: 壊れたURL・不要なインデックスの詳細と修正手順
A12: GSC主要発見 | B12: 前回報告の発見1〜5の詳細
A13: クエリ機会 | B13: あと一歩のクエリ・急伸クエリ・クリック0のクエリ
A14: 推移・デバイス | B14: 週次推移・期間別・デバイス別の数値
A15: アフィリエイト実績 | B15: A8.net・バリューコマース・もしもアフィリエイトの実績と診断
A17: 使用データ
A18: データ | B18: 内容
A19: Googleサーチコンソール | B19: 検索パフォーマンス（ウェブ）過去3か月 2026-07-07〜2026-10-06／過去28日／過去7日。クエリ・ページは画面エクスポートの上位1,000行
A20: A8.net | B20: 月次レポート・プログラム別（2026年1月〜10月）
A21: バリューコマース | B21: 広告主別・日別（2026/09/10〜10/10）
A22: もしもアフィリエイト | B22: サイト別KPI（期間はエクスポート時の設定）
A24: 前提・制約（必ずお読みください）
A25: ・分析環境からサイトに接続できなかったため、記事本文と現在のアフィリエイトリンクの配置は確認していません。現在のタイトルは検索結果で確認できたものだけ記載しています。
A26: ・カニバリゼーションは推定です。GSCの画面エクスポートには「どのクエリでどの記事が表示されたか」の組み合わせが含まれないため、クエリの文言と記事のテーマから判定しました。確定には「カニバリ分析」シートの手順でGSCを確認してください。
A27: ・「関連クエリ（推定）」は、記事マスタ（data/articles/article_master.csv）のパターンでクエリを記事に割り当てたものです。1つのクエリが複数の記事に割り当たることがあります。
A28: ・クエリ表は上位1,000行で、匿名化されたクエリは含みません。クエリの合計はサイト全体の合計より小さくなります。サイト全体の合計はデバイス別の値を使っています。
A29: ・マイクロコピー中のサービス仕様（無料で口コミを見られる条件、年収の目安など）は公式情報で確認していません。掲載前に必ず公式サイトとASPの規約を確認してください。
A30: ・優先順位は「（月間クリック＋取りこぼし見込み）× テーマの収益性 ＋ カニバリの深刻度」のスコアに、人の判断（重点9記事の固定など）を加えて決めています。
A32: 目標CTR（平均掲載順位別）※「全記事_修正点」の取りこぼし見込みの計算に使用。数値を変えると再計算されます
A33: 想定値の根拠：サイト内で3か月の表示300回以上の記事の実績（6〜9位の中央値は約3.5%、5位は約10%）を基に、上位水準として設定。
A34: 平均掲載順位 | B34: 目標CTR
A35: 1 | B35: 0.3
A36: 2 | B36: 0.2
A37: 3 | B37: 0.14
A38: 4 | B38: 0.1
A39: 5 | B39: 0.08
A40: 6 | B40: 0.06
A41: 7 | B41: 0.05
A42: 8 | B42: 0.045
A43: 9 | B43: 0.04
A44: 10 | B44: 0.035
...

Sheet サマリー
A1: サマリー：結論と主要指標
A3: 結論（3行）
A4: ① 集客は立ち上がっている（クリック/日 119→157→202）。一方で収益導線が主要記事にほぼ無く、アフィリエイトのクリックは流入の約0.5%。収益0円の最大の原因は「配置の良し悪し」以前に「主要記事に導線がない」こと。
A5: ② 最初の収益源は転職会議（バリューコマース・無料会員登録）。9/12に1件・330円が実際に発生（未承認）しており、OpenWork・企業研究・ブラック求人の読者と最も相性が良い。
A6: ③ カニバリは全体の順位低下の原因ではない（平均順位8.9→7.1に改善）。ただし転職会議・リクルートエージェント・AI履歴書・書類選考・SIer一覧など一部のグループでは評価の分散が起きている。
A8: 検索パフォーマンス（期間別）
A9: 期間 | B9: 日数 | C9: クリック | D9: 表示回数 | E9: CTR | F9: クリック/日 | G9: 平均掲載順位
A10: 過去3か月 | B10: 92 | C10: 10933 | D10: 227520 | E10: =C10/D10 -> 0.048052918 | F10: =C10/B10 -> 118.83696 | G10: 8.22
A11: 過去28日 | B11: 28 | C11: 4386 | D11: 86715 | E11: =C11/D11 -> 0.050579485 | F11: =C11/B11 -> 156.64286 | G11: 7.56
A12: 過去7日 | B12: 7 | C12: 1417 | D12: 27303 | E12: =C12/D12 -> 0.051899059 | F12: =C12/B12 -> 202.42857 | G12: 7.14
A14: 収益の現状（アフィリエイト）
A15: ASP | B15: 表示 | C15: クリック | D15: 発生件数 | E15: 発生金額（円） | F15: メモ
A16: バリューコマース（9/10〜10/10） | B16: 646 | C16: 22 | D16: 1 | E16: 330 | F16: 転職会議で1件・330円発生（未承認）。じゃらん・一休は無関係な広告
A17: A8.net（10月・途中） | B17: 51 | C17: 2 | D17: 0 | E17: 0 | F17: 表示が7月324→10月51と減少（流入増と逆行）
A18: もしもアフィリエイト | B18: 90 | C18: 5 | D18: 0 | E18: 0 | F18: 期間はエクスポート時の設定
A19: 合計 | B19: =SUM(B16:B18) -> 787 | C19: =SUM(C16:C18) -> 29 | D19: =SUM(D16:D18) -> 1 | E19: =SUM(E16:E18) -> 330
A20: 検索流入（28日・月換算）に対するアフィリエイトクリック率（VC＋A8の直近月） | F20: =(C16+C17)/(4386/28*30) -> 0.0051071591
A22: 仮説の検証結果
A23: 仮説 | B23: 判定 | C23: 根拠
A24: カニバリで順位が低下している | B24: 一部のみ正しい | C24: サイト全体の平均順位は8.9→7.1に改善しており、全体の主因ではない。ただし転職会議・リクルートエージェント・AI履歴書・書類選考・SIer一覧・応募経路などのグループで評価の分散が強く疑われ、AI履歴書記事は7.5→8.6位に実際に低下。
A25: アフィリエイト導線・配置が悪い | B25: 正しい（配置以前の問題） | C25: 検索流入 月約4,700に対し、ASPの表示は流入の1〜2割程度と推定。A8の表示は流入が倍増したのに7月324→10月51へ減少。主要記事にそもそも導線がない可能性が高い。
A26: CTRをさらに伸ばす必要がある | B26: 記事によって正しい | C26: OpenWorkグラフ記事（18.6%）や富士通記事（7.2%）は十分高い。転職会議系（1.0〜1.9%）、IPA改編（2.5%）、AI履歴書（0.7%）、アットホーム（1.0%）、「社名変更 やばい」（2位でCTR2%）は明確に低い。
A28: 最優先の対応（今週〜2週間）
A29: No | B29: 対応 | C29: 内容
A30: 1 | B30: 無関係な広告の撤去 | C30: バリューコマースのじゃらんnet・一休.comの表示元（自動広告・ウィジェット等）を特定して撤去
A31: 2 | B31: 壊れたURLの修正 | C31: 「URL・技術課題」シートの手順で、https抜けリンク・末尾「]」・www付きを修正
A32: 3 | B32: A8広告の棚卸し | C32: 流入増に反して表示が減っている原因（バナーの削除・設置記事の偏り）を確認
A33: 4 | B33: 重点記事（優先1） | C33: /tenshokukaigi-kuchikomi-mikata-tsukaikata/：導線の設置 → 2週間後にタイトル変更（詳細は「重点9記事_詳細」）
A34: 5 | B34: 重点記事（優先2） | C34: /openwork-tsukaikata/：導線の設置 → 2週間後にタイトル変更（詳細は「重点9記事_詳細」）
A35: 6 | B35: 重点記事（優先3） | C35: /openwork-graph-mikata/：導線の設置 → 2週間後にタイトル変更（詳細は「重点9記事_詳細」）
A36: 7 | B36: 重点記事（優先4） | C36: /fujitsu-nenshu-hyouka-jinji-me/：導線の設置 → 2週間後にタイトル変更（詳細は「重点9記事_詳細」）
A37: 8 | B37: 重点記事（優先5） | C37: /recruit-agent-hyoban/：導線の設置 → 2週間後にタイトル変更（詳細は「重点9記事_詳細」）
A38: 9 | B38: 重点記事（優先6） | C38: /ipa-exam-reform-2027/：導線の設置 → 2週間後にタイトル変更（詳細は「重点9記事_詳細」）
A39: 10 | B39: 重点記事（優先7） | C39: /rirekisho-ai-bareru/：導線の設置 → 2週間後にタイトル変更（詳細は「重点9記事_詳細」）
A40: 11 | B40: 重点記事（優先8） | C40: /instant-offer-one-interview-black-company-warning/：導線の設置 → 2週間後にタイトル変更（詳細は「重点9記事_詳細」）
A41: 12 | B41: 重点記事（優先9） | C41: /it-tensyoku-agent-osusume/：導線の設置 → 2週間後にタイトル変更（詳細は「重点9記事_詳細」）

Sheet 良い点・悪い点
A1: 現状のブログの良い点・悪い点
A2: 根拠データと、それぞれの活かし方・対策
A3: 区分 | B3: 分類 | C3: 内容 | D3: 根拠データ | E3: 活かし方・対策
A4: 良い点 | B4: SEO | C4: 検索流入が急成長している | D4: クリック/日：3か月平均119 → 直近28日157 → 直近7日202。週次で約650→1,364クリックに倍増 | E4: 伸びている今のうちに導線を整えれば、収益化の機会がそのまま増える
A5: 良い点 | B5: SEO | C5: 平均掲載順位が改善している | D5: サイト全体の平均順位 8.9位（7月上旬）→ 7.1位（直近7日） | E5: カニバリで全体の順位が落ちているわけではない。局所的な整理で十分
A6: 良い点 | B6: コンテンツ | C6: 「現役IT人事」という一次情報の切り口が強い | D6: OpenWorkグラフ記事 CTR18.6%、ITストラテジスト廃止 CTR19%、DBスペシャリスト廃止 CTR16%、リクルートエージェント評判 CTR9.9% | E6: 「企業側から見た〜」をタイトル・導線の両方で打ち出す。これが他サイトに真似できない差別化
A7: 良い点 | B7: コンテンツ | C7: 勝ちパターンの型がある（試験名＋なくなる、口コミサイト＋見方） | D7: *-haishiシリーズの主要クエリは1〜7位、OpenWork「形」「見方」で1〜2位 | E7: 同じ型を応用情報（新規）・転職会議・他社企業研究に横展開
A8: 良い点 | B8: コンテンツ | C8: 時事・需要の波を捉えている | D8: IPA改編2027の表示2.8倍、富士通年収の日次クリック4→23、NEC AI部署の表示3倍 | E8: 最終更新日の明記と追記で、需要のピークを取り切る
A9: 良い点 | B9: 収益 | C9: 転職会議で成果発生の実績がある | D9: VC：転職会議 242表示・3クリック・1件発生（330円・未承認） | E9: OpenWork・企業研究・ブラック求人の読者と最も相性が良い案件として全面展開
A10: 良い点 | B10: SEO | C10: モバイルの順位・CTRが良好 | D10: 直近28日：モバイル CTR5.7%・7.0位／PC 4.0%・8.6位 | E10: ボタン・ボックスはスマホでの見え方を最優先で設計
A11: 悪い点 | B11: 収益 | C11: 収益導線が主要記事にほぼ存在しない | D11: 検索流入 月約4,700に対し、アフィリエイトのクリックは全ASP合計で月約25（約0.5%）。A8の表示は7月324→10月51と、流入増に反して減少 | E11: 上位9記事に導線を設置。A8広告の設置場所を棚卸し
A12: 悪い点 | B12: 収益 | C12: 読者と無関係な広告が表示されている | D12: VC：じゃらんnet 34表示、一休.com 34表示（クリック0） | E12: 表示元（自動広告・ウィジェット等）を特定して撤去
A13: 悪い点 | B13: 収益 | C13: 流入の大半が「調べもの」で転職意欲の低い層 | D13: 流入上位はOpenWorkの使い方・試験の廃止情報。エージェント評判などの転職サービス記事への流入は全体の約6%（直近28日） | E13: いきなりエージェントではなく、転職会議（無料登録）→スカウト→エージェントの順で段階的に誘導
A14: 悪い点 | B14: SEO | C14: 上位記事への依存度が高い | D14: 上位10記事でクリックの68%。OpenWorkグラフ記事1本で、3か月では約25%、直近28日でも約17% | E14: 第2・第3の柱（富士通・NEC・IPA）を育てて分散
... A18: 悪い点 | B18: コンテンツ | C18: 表示がほぼない記事が多い | D18: 139記事中、3か月の表示が100回未満の記事が45本（うち50回未満が27本）。選考対策（32本中18本）とキャリア・働き方（14本中10本）に集中 | E18: 統合・リライト・新規作成の判断を明確にし、柱テーマに集中

Sheet 今後の方向性
A1: 今後のブログの方向性
A2: データから見た「勝てる領域」と「収益につながる領域」の重なりに集中する
A3: 1. ポジショニング
A4: 項目 | B4: 内容
A5: ポジション | B5: 「求人を出す側（企業・人事）から見た転職のウラ側」を語れる、現役IT人事のメディア
A6: 読者 | B6: IT業界で転職を考え始めた20代後半〜40代のエンジニア・SE、および大手IT企業の社員
A7: 差別化 | B7: 他の転職ブログは求職者目線か、エージェントの宣伝目線。本サイトは「企業側が実際にどう見ているか」を語れる唯一の立場。タイトル・見出し・導線のすべてで「企業側から見ると」を打ち出す
A8: 収益モデル | B8: ①転職会議（無料会員登録・低ハードル）で初収益 → ②スカウト型（レバテックダイレクト）で中間層 → ③エージェント（リクルートエージェント・JAC）で高単価、の3段階
A10: 2. 注力テーマ（6本柱）と現状の数値
A11: テーマ | B11: 役割 | C11: 記事数 | D11: 月間クリック（28日換算） | E11: 伸び率（直近28日／それ以前） | F11: 方針 | G11: 主な案件
A12: 口コミサイト活用 | B12: 集客＋収益（最優先） | C12: 9 | D12: 1686 | E12: =IFERROR(56.214/46.844,0) -> 1.2000256 | F12: OpenWorkで勝っている型を転職会議に横展開。「2サイトで裏取り」という人事の本音で転職会議へ送客 | G12: 転職会議（VC）
A13: IT企業研究 | B13: 収益（育成） | C13: 14 | D13: 1115 | E13: =IFERROR(37.179/11.141,0) -> 3.3371331 | F13: 富士通・NECの成功を他社へ横展開（NTTデータ・日立・CTC・SCSK・TIS・NRI等）。年収・等級・退職金・早期退職など社員と転職検討者の両方の需要を取る | G13: JAC・リクルートエージェント（VC）、レバテックダイレクト（A8）
A14: 転職サービス評判 | B14: 収益（直結） | C14: 22 | D14: 287 | E14: =IFERROR(9.571/1.766,0) -> 5.4195923 | F14: 提携済み案件（リクルートエージェント・JAC・リクナビNEXT・Geekly・レバテックダイレクト）の評判記事を「企業側から見た評価」で強化。おすすめ記事をハブに | G14: 各サービス
A15: 求人票・ブラック企業 | B15: 集客＋収益 | C15: 10 | D15: 153 | E15: =IFERROR(5.107/8.547,0) -> 0.5975196 | F15: 唯一縮小中のテーマ。チェックリスト記事をハブに再整備し、「応募前の確認＝転職会議」の導線を統一 | G15: 転職会議（VC）、リクルートエージェント（VC）
A16: IPA試験・IT資格 | B16: 集客（信頼） | C16: 21 | D16: 1257 | E16: =IFERROR(41.893/30.516,0) -> 1.3728208 | F16: 需要は最大だが転職意欲は低い。順位とCTRを取り切り、ソフト導線（スカウト）で段階的に収益化。応用情報の単独記事を新設 | G16: レバテックダイレクト（A8）、資格講座（要提携）
A17: 選考対策 | B17: 収益（育成） | C17: 32 | D17: 76 | E17: =IFERROR(2.536/1.594,0) -> 1.5909661 | F17: 記事が分散しすぎ。書類・面接・AI書類の3ハブに統合し、「書類添削・面接対策は無料でエージェントに」で送客 | G17: リクルートエージェント（VC）
A18: 上記以外（キャリア・働き方／SIer・SES業界研究／サイト基本ページ）：31記事・月間約136クリック
A20: 3. やめること・減らすこと
A21: 項目 | B21: 理由
A22: 新規テーマを広げない | B22: 選考対策・キャリア系の単発記事の多くが3か月の表示100回未満。当面は上記6テーマ以外の新規記事を作らない
A23: 同じ意図の記事を増やさない | B23: 書類選考・SIer一覧・AI履歴書のように、似た記事を量産すると評価が分散する。新規記事の前に既存記事への追記で足りないかを必ず確認
A24: 上位記事の大幅リライト | B24: OpenWorkグラフ記事（CTR18.6%）など好調な記事は、導線の追加だけに留める
A25: 読者と無関係な広告 | B25: じゃらん・一休などの案件や自動広告は信頼を損なう
A27: 4. 新規記事・追記の候補
A28: 仮URL・記事 | B28: 狙うクエリ | C28: 根拠 | D28: 優先度
A29: /ouyou-jouhou-haishi/ | B29: 応用情報技術者試験 なくなる／いつまで／2027 | C29: 関連クエリ計4,000表示超、総合記事で10位・CTR1%未満。*-haishiシリーズは勝ちパターン | D29: S
A30: NTTデータ・日立・CTC・SCSKの「年収・等級」記事 | B30: 〇〇 年収／〇〇 等級 年収 | C30: 富士通の年収記事が日次クリック4→23に急伸。企業研究は収益化しやすい | D30: A
A31: IT転職の面接対策ハブ | B31: 転職 二次面接 落ちる／最終面接 対策 | C31: 面接系6記事が分散し、いずれも表示が小さい | D31: B
A32: 転職会議の無料で見る方法（親記事の強化で代替可） | B32: 転職会議 裏ワザ／登録せずに | C32: 「裏ワザ」254表示・クリック0、「登録せずに」182表示 | D32: A（新規ではなく親記事への追記で対応）
A34: 5. ロードマップ
A35: 期間 | B35: 施策 | C35: 完了の目安
A36: 今週 | B36: 無関係な広告の撤去・壊れたURLの修正・A8広告の棚卸し | C36: じゃらん・一休の表示0、壊れたURLの301設定完了
A37: 〜2週間 | B37: 重点9記事（S）の導線設置とタイトル変更（導線→2週間後にタイトル、の順で時期をずらす） | C37: アフィリエイトクリック 月100
A38: 〜1か月 | B38: A評価記事のタイトル・説明文修正、転職会議・リクルートエージェント・AI履歴書のカニバリ解消 | C38: 転職会議系CTR 4%
A39: 〜2か月 | B39: 応用情報の新記事、書類選考・SIer・応募経路の統合（301） | C39: 統合した記事の順位が親記事に集約
A40: 〜3か月 | B40: 企業研究シリーズの横展開、選考対策ハブの整備、GSC APIで「クエリ×ページ」データを取得しカニバリを自動判定 | C40: アフィリエイトクリック 月250、発生10件
A42: 6. KPI（目標値は目安。2〜4週間ごとに見直し）
A43: KPI | B43: 現状 | C43: 1か月後 | D43: 3か月後 | E43: 計測方法
A44: アフィリエイトクリック／月（全ASP） | B44: 25 | C44: 100 | D44: 250 | E44: VC・A8・もしもの管理画面
A45: 流入に対するアフィリエイトクリック率 | B45: 0.005 | C45: 0.02 | D45: 0.04 | E45: 上記÷GSCクリック
...

Sheet 全記事_修正点
A1: 全記事の修正点（優先順）
A2: 優先度 S：今週〜2週間／A：今月中／B：来月／C：3か月以内（統合・整理）／D：様子見。灰色の列は数値、白い列が修正内容
A3: 凡例：取りこぼし見込み＝表示/日（28日）×30×（目標CTR−CTR（28日））。目標CTRは「目次・前提」シートの表を参照（変更すると再計算）。「所見」が「個別に判断」の行は人が個別に書いた修正案、「自動診断」の行はデータから自動生成した修正案。
A4: 優先順位 | B4: 優先度 | C4: 対応時期 | D4: 記事URL | E4: テーマ | F4: 競合グループ | G4: 3か月表示 | H4: 3か月クリック | I4: 3か月CTR | J4: 平均順位（3か月） | K4: 平均順位（28日） | L4: クリック/日（以前） | M4: クリック/日（28日） | N4: 傾向 | O4: 月間クリック（換算） | P4: 表示/日（28日） | Q4: CTR（28日） | R4: 目標CTR | S4: 取りこぼし見込み（クリック/月） | T4: 関連クエリ（推定・表示上位3） | U4: 診断（課題） | V4: カニバリ判定 | W4: カニバリの詳細 | X4: SEO・コンテンツの修正点 | Y4: タイトル・説明文の修正点 | Z4: アフィリエイト導線の修正点 | AA4: 推奨案件（ASP） | AB4: 工数 | AC4: 所見
A5: 1 | B5: S | C5: 今週〜2週間 | D5: /tenshokukaigi-kuchikomi-mikata-tsukaikata/ | E5: 口コミサイト活用 | F5: 転職会議 | G5: 15283 | H5: 147 | I5: =IFERROR(H5/G5,0) -> 0.0096185304 | J5: 9.7 | K5: 9.5 | L5: 1.48 | M5: 1.86 | N5: 横ばい | O5: =M5*30 -> 55.8 | P5: 174.8 | Q5: 0.0106 | R5: =IF(K5="",0,INDEX(目次・前提!$B$35:$B$54,MIN(20,MAX(1,ROUND(K5,0))))) -> 0.035 | S5: =MAX(0,P5*30*(R5-Q5)) -> 127.9536 | T5: 転職会議（1,646表示・9.6位・CTR0.5%） / 転職会議 口コミ 見る方法（1,027表示・9.5位・CTR0.6%） / 転職会議 危ない（581表示・7.9位・CTR0.0%） | U5: 3か月15,283表示（転職会議系で最大）なのにCTR1.0%・9.7位。「転職会議」1,646表示9.6位CTR0.5%、「口コミ 見る方法」1,027表示9.5位、「危ない」581表示クリック0。転職会議はVCで成果発生実績（9/12・330円）がある唯一の案件で、サイトで最も収益に近い記事。 | V5: 強 | W5: 【転職会議】競合相手：/tenshokukaigi-openwork-comparison/、/tenshokukaigi-cancel-withdrawal/、/tenshokukaigi-toroku-bareru/ | X5: 転職会議系の親記事に位置付け、「危ない？評判は？」「無料で見る裏ワザ」「登録せずに見る方法」の見出しを追加。比較・身バレ・退会の詳細は各専門記事に任せて3行要約＋リンク。冒頭に目的別リンク（比較／バレる／退会）。 | Y5: 【案A】【人事が解説】転職会議の口コミを無料で見る方法｜危ない？評判も本音で 【案B】転職会議の口コミの見方｜無料で全部見る方法と「危ない」の真相【現役人事】 【説明文】転職会議の口コミを無料で見る方法を現役IT人事が画面付きで解説。「危ない」「登録するとバレる？」への答えと、採用側から見た口コミの正しい読み方、OpenWorkとの使い分けまで。 | Z5: ①冒頭の結論ボックス：ボタン「転職会議で気になる会社の口コミを見る（無料）」 ②手順1の中：テキストリンク「まずは公式ページで無料会員登録→」 ③「危ない？」の不安を解消した直後：「人事の立場から言うと、投稿者が特定されることはまずない」→ボタン ④記事末の人事の本音ボックス：「面接で口コミの話題を出す企業は多い。面接体験談まで読んだ候補者は準備の深さが違う」→ボタン ※ボタンは3か所まで。登録条件は公式の最新情報で要確認 | AA5: 転職会議(VC) | AB5: 中 | AC5: 個別に判断
A6: 2 | B6: S | C6: 今週〜2週間 | D6: /openwork-tsukaikata/ | E6: 口コミサイト活用 | F6: OpenWork | G6: 25323 | H6: 1004 | I6: =IFERROR(H6/G6,0) -> 0.039647751 | J6: 6.5 | K6: 6 | L6: 9.81 | M6: 13.43 | N6: 横ばい | O6: =M6*30 -> 402.9 | P6: 237.8 | Q6: 0.0565 | R6: =IF(K6="",0,INDEX(目次・前提!$B$35:$B$54,MIN(20,MAX(1,ROUND(K6,0))))) -> 0.06 | S6: =MAX(0,P6*30*(R6-Q6)) -> 24.969 | T6: openwork 口コミ 見るには（2,107表示・4.0位・CTR10.0%） / オープンワーク 口コミ 見るには（861表示・3.5位・CTR9.5%） / オープンワーク 見方（419表示・1.1位・CTR49.2%） | U6: 3か月25,323表示でサイト最大。28日CTR5.7%（3か月4.0%から改善中）・6.0位。「openwork 口コミ 見るには」2,107表示4.0位CTR10%は取れているが、「オープンワーク 口コミ」340表示7.0位CTR0.3%、「〜見るには 学生」294表示8.1位を取りこぼし。月約400クリックあるのに、ASPの表示数から見て収益導線がほぼない。 | V6: 中 | W6: 【OpenWork】競合相手：/openwork-graph-mikata/、/openwork-white-company-mikata/、/openwork-toroku-bareru/、/openwork-hikaku-kinou/ | X6: バレる解説は3行要約＋/openwork-toroku-bareru/へのリンクに縮小し、「口コミを見る方法（投稿・Web履歴書・学生）」「見れない時の対処」に集中。学生向け見出しを新設。「あてにならない」「サクラ」（計300表示超）に答える見出しを追加。 | Y6: 【案A】OpenWorkの口コミを見るには？無料で見る3つの方法【現役人事が解説】 【案B】OpenWork（オープンワーク）の使い方｜口コミを無料で見る方法と見れない時の対処 【説明文】OpenWorkの口コミを無料で見る方法を現役IT人事が解説。口コミ投稿・Web履歴書・学生の場合の見方、「見れない」時の対処、登録で会社にバレるかまで。採用側が実際に見ているポイントも紹介。 | Z6: ①「口コミが見れない時の対処」：OpenWorkで投稿したくない人向けの代替として転職会議（テキストリンク。閲覧条件は公式で要確認） ②「口コミの正しい読み方」の末尾に人事の本音ボックス：「口コミは辞めた人ほど書くので1サイトだと偏る。私は他社を調べる時、2サイトで同じ傾向が出るか必ず確認する」→ボタン「転職会議で同じ会社の口コミを見比べる（無料）」 ③記事末：「部署ごとの実態はエージェントに聞くのが早い」→/it-tensyoku-agent-osusume/ | AA6: 転職会議(VC) | AB6: 中 | AC6: 個別に判断
A7: 3 | B7: S | C7: 今週〜2週間 | D7: /openwork-graph-mikata/ | E7: 口コミサイト活用 | F7: OpenWork | G7: 15454 | H7: 2754 | I7: =IFERROR(H7/G7,0) -> 0.17820629 | J7: 4.5 | K7: 4.4 | L7: 31.09 | M7: 27.29 | N7: 横ばい | O7: =M7*30 -> 818.7 | P7: 146.5 | Q7: 0.1863 | R7: =IF(K7="",0,INDEX(目次・前提!$B$35:$B$54,MIN(20,MAX(1,ROUND(K7,0))))) -> 0.1 | S7: =MAX(0,P7*30*(R7-Q7)) -> 0 | T7: オープンワーク 形（1,260表示・1.8位・CTR33.4%） / オープンワーク 見方（419表示・1.1位・CTR49.2%） / オープンワーク 評価 目安（387表示・4.6位・CTR8.3%） | U7: 月約820クリック・4.4位・CTR18.6%のサイト最大の稼ぎ頭（検索流入の約17%）。「オープンワーク 形」1,260表示1.8位など1〜2位を多数獲得し、SEOは完成度が高い。課題は収益導線だけ。この1記事が落ちるとサイト全体が約2割落ちる依存構造。 | V7: 中 | W7: 【OpenWork】競合相手：/openwork-tsukaikata/、/openwork-white-company-mikata/、/openwork-toroku-bareru/、/openwork-hikaku-kinou/ | X7: 本文の大幅リライトは禁止（順位を崩すリスク）。「ダイヤモンド型／逆ダイヤ型」（計260表示超・5〜6位）と「評価の目安・何点以上・平均点」（計550表示超）の小見出しを追加。目次見出しを検索語と同じ言葉にして、ジャンプリンク経由のクリックを増やす。 | Y7: タイトルは原則変更しない（CTR18.6%は4位台として非常に高い）。説明文の末尾に「危険なグラフの形3パターンも図解」を追加する程度に留める。 | Z7: ①「要注意なグラフの形」の直後：「気になる形が出たら退職理由の口コミを確認。転職会議は退職理由の口コミが多い」→ボタン「転職会議でこの会社の退職理由を見る（無料）」 ②「人事はグラフをこう見る」の末尾：「応募前にエージェント経由で離職率・配属を確認する候補者は強い」→リクルートエージェント ③記事末：ボタンは1つだけ（選択肢を並べない） ※追加は計3か所まで | AA7: 転職会議(VC)/リクルートエージェント(VC) | AB7: 小 | AC7: 個別に判断
A8: 4 | B8: S | C8: 今週〜2週間 | D8: /fujitsu-nenshu-hyouka-jinji-me/ | E8: IT企業研究 | F8: 富士通 | G8: 17389 | H8: 906 | I8: =IFERROR(H8/G8,0) -> 0.052101904 | J8: 6.8 | K8: 5.8 | L8: 4.2 | M8: 22.75 | N8: 急伸 | O8: =M8*30 -> 682.5 | P8: 316.7 | Q8: 0.0718 | R8: =IF(K8="",0,INDEX(目次・前提!$B$35:$B$54,MIN(20,MAX(1,ROUND(K8,0))))) -> 0.06 | S8: =MAX(0,P8*30*(R8-Q8)) -> 0 | T8: 富士通 年収（1,136表示・11.2位・CTR4.1%） / 富士通 シニアマネージャー 年収（348表示・5.7位・CTR6.0%） / 富士通 レベル（309表示・6.5位・CTR5.2%） | U8: 日次クリック4.2→22.8に急伸し月約680クリック（2番目の柱）。等級・役職別クエリは4〜6位で強いが、親キーワード「富士通 年収」1,136表示は11.2位・CTR4.1%で1ページ目外。「富士通 40歳年収」「事業部長 年収」はクリック0。読者は社員（自分の等級確認）と転職検討者の2種類。 | V8: なし | W8: 同じ意図の記事なし | X8: タイトル先頭を「富士通の年収」にして親キーワードを狙う。年齢別（30/35/40歳）の年収表と、事業部長・執行役員の行を追加。「富士通 給料」（49表示20.7位）「給与体系」もカバー。最終更新日を明記。 | Y8: 【案A】富士通の年収はいくら？レベル別・役職別・年齢別の実態【現役IT人事】 【案B】富士通の年収をレベル9〜15・役職別に解説｜40歳・管理職の実額も 【説明文】富士通の年収をFJレベル（9〜15）・役職・年齢別に整理。ジョブ型人事制度で何が変わったか、中途入社で何レベルからスタートできるかを現役IT人事の目線で解説。 | Z8: 読者を2種類に分ける。 ①レベル別年収表の直下（転職検討者向け）：「中途で何レベルから始まるかはオファー前の交渉でほぼ決まる。ハイクラスに強いエージェント経由の候補者は交渉材料を持っていることが多い」→JAC Recruitment ②「ジョブ型・評価」の末尾（社員向け）：「今のレベルが市場でどう評価されるかはスカウトを受けるのが早い。登録だけなら社内にバレない」→レバテックダイレクト ③記事末：2択ボタン「富士通に転職したい人→」「富士通から転職を考えている人→」 | AA8: JAC Recruitment(VC)/レバテックダイレクト(A8) | AB8: 中 | AC8: 個別に判断
A9: 5 | B9: S | C9: 今週〜2週間 | D9: /recruit-agent-hyoban/ | E9: 転職サービス評判 | F9: リクルートエージェント | G9: 2082 | H9: 203 | I9: =IFERROR(H9/G9,0) -> 0.097502402 | J9: 5.4 | K9: 5.1 | L9: 0.44 | M9: 6.25 | N9: 急伸 | O9: =M9*30 -> 187.5 | P9: 63 | Q9: 0.0992 | R9: =IF(K9="",0,INDEX(目次・前提!$B$35:$B$54,MIN(20,MAX(1,ROUND(K9,0))))) -> 0.08 | S9: =MAX(0,P9*30*(R9-Q9)) -> 0 | T9: リクルートエージェント 面接後 アンケート（52表示・3.9位・CTR21.1%） / リクルートエージェント 面接後のアンケート（49表示・3.9位・CTR22.4%） / リクルートエージェント アンケート（44表示・4.3位・CTR2.3%） | U9: 日次クリック0.4→6.2に急伸、5.1位・CTR9.9%の収益直結記事（VCにリクルートエージェント案件あり）。ただしVCのリクルートエージェント広告は30日で321表示・6クリック（1.9%）で、表示されてもクリックされていない。関連クエリの上位が「面接後アンケート」系で、本来の「評判」系クエリが上位1,000件に入っていない。 | V9: 強 | W9: 【リクルートエージェント】競合相手：/recruit-agent-tsukaikata/ | X9: 担当を「評判・口コミ・ひどい・向いてる人」（登録前の判断）に限定。「面接後アンケート」「求人ポスト」の詳細は/recruit-agent-tsukaikata/に移して要約＋リンク。「企業側（求人を出す側）から見た実態」という一次情報を見出しで強調。 | Y9: 【案A】リクルートエージェントの評判は？現役人事が「企業側から見た実態」を本音で解説 【案B】リクルートエージェントの評判・口コミ｜ひどい？向いてる人を採用担当が解説 【説明文】リクルートエージェントの評判を、求人を出す側の現役IT人事が本音で解説。「ひどい」と言われる理由、担当者の当たり外れを避ける方法、向いている人・いない人を企業側の視点で。 | Z9: ①冒頭の結論ボックス：「企業側から見ても、まず求人を出すのがリクルート。非公開求人の量は別格」→ボタン「リクルートエージェントに無料登録（約5分）」 ②「悪い評判」の末尾：「担当変更は依頼できる。最初の面談で希望をはっきり伝えるのがコツ」→テキストリンク ③「向いていない人」：年収600万円以上の管理職志向→JAC、ITエンジニアでスカウト型→レバテックダイレクト（合わない人に別サービスを示すと信頼が上がる） ④記事末：ボタン | AA9: リクルートエージェント(VC) | AB9: 中 | AC9: 個別に判断
A10: 6 | B10: S | C10: 今週〜2週間 | D10: /ipa-exam-reform-2027/ | E10: IPA試験・IT資格 | F10: IPA改編 | G10: 19660 | H10: 503 | I10: =IFERROR(H10/G10,0) -> 0.025584944 | J10: 8 | K10: 8.1 | L10: 3.67 | M10: 9.57 | N10: 急伸 | O10: =M10*30 -> 287.1 | P10: 385 | Q10: 0.0249 | R10: =IF(K10="",0,INDEX(目次・前提!$B$35:$B$54,MIN(20,MAX(1,ROUND(K10,0))))) -> 0.045 | S10: =MAX(0,P10*30*(R10-Q10)) -> 232.155 | T10: 応用情報技術者試験 なくなる（2,424表示・9.9位・CTR0.9%） / 応用情報技術者試験（603表示・3.4位・CTR5.0%） / 応用情報 なくなる（488表示・9.1位・CTR0.4%） | U10: 3か月19,660表示、表示/日139→385（2.8倍）でサイトで最も需要が伸びている記事。しかし8.0位・CTR2.5%。「応用情報技術者試験 なくなる」2,424表示9.9位CTR0.9%、「応用情報 なくなる」488表示CTR0.4%。試験別の単独記事（ITストラテジストCTR19%、DBスペシャリスト16%）は勝てる型なのに、応用情報だけ単独記事がない。 | V10: 中 | W10: 【IPA改編】競合相手：/ipa-exam-reform-career-impact/、/professional-digital-skill-exam/、/data-management-exam/ | X10: 新規記事/ouyou-jouhou-haishi/（仮）を作成し「応用情報はなくなる？いつまで受けられる？」に特化。本記事の応用情報セクションは要約＋リンク。本記事は「改編の全体像・試験別一覧」のハブにし、高度試験の*-haishi記事・ITパスポート/基本情報記事へ分岐。冒頭に最終更新日と「確定情報/未確定情報」を明記。 | Y10: 【案A】【2027年】IPA試験はどう変わる？応用情報・高度試験の廃止と新試験を一覧で解説 【案B】情報処理技術者試験の2027年改編まとめ｜なくなる試験・いつまで受けられるか 【説明文】2027年の情報処理技術者試験の改編で、応用情報や高度試験はなくなるのか、いつまで受けられるのかを一覧で整理。今から受けるべき試験を現役IT人事が採用時の評価目線で解説。 【新記事タイトル案】応用情報技術者試験はなくなる？いつまで受けられるか・2027年以降の扱いを解説 | Z10: 読者は資格学習中で転職意欲は低い→ソフト導線のみ。 ①「資格は転職でどう評価されるか」（なければ新設）：「採用側は資格を実務経験の裏付けとして見る。自分の経験がどう評価されるかは、スカウト型に職務経歴だけ登録しておくと分かる」→レバテックダイレクト ②記事末：資格講座案件（スタディング等）は各ASPで提携可否・報酬を確認のうえ検討 | AA10: レバテックダイレクト(A8) | AB10: 大 | AC10: 個別に判断
A11: 7 | B11: S | C11: 今週〜2週間 | D11: /rirekisho-ai-bareru/ | E11: 選考対策 | F11: AI応募書類 | G11: 3319 | H11: 24 | I11: =IFERROR(H11/G11,0) -> 0.0072310937 | J11: 7.5 | K11: 8.6 | L11: 0.14 | M11: 0.54 | N11: 横ばい | O11: =M11*30 -> 16.2 | P11: 42.8 | Q11: 0.0125 | R11: =IF(K11="",0,INDEX(目次・前提!$B$35:$B$54,MIN(20,MAX(1,ROUND(K11,0))))) -> 0.04 | S11: =MAX(0,P11*30*(R11-Q11)) -> 35.31 | T11: 履歴書 ai バレる（767表示・6.3位・CTR0.4%） / 職務経歴書 ai バレる（389表示・12.0位・CTR0.5%） / 職務経歴書 chatgpt バレる（134表示・10.2位・CTR0.0%） | U11: 3か月3,319表示・7.5位なのにCTR0.7%（同順位帯のサイト標準は約3.5%）。直近28日は8.6位に低下（今回唯一、カニバリによる順位低下と言える事例）。「履歴書 ai バレる」767表示6.3位CTR0.4%、「職務経歴書 ai バレる」389表示12.0位、「職務経歴書 chatgpt バレる」134表示クリック0。現行タイトル（検索結果で確認）は長く、答えが見えず「暴露」が煽りに見える。 | V11: 強 | W11: 【AI応募書類】競合相手：/shokumukeirekisho-ai-chatgpt-sakusei/、/ai-buntai-rirekisho-syokumukerekisho/、/ai-mensetsu-shorui-senko/ | X11: AI×応募書類の記事を整理。/ai-buntai-rirekisho-syokumukerekisho/を本記事に統合して301。/shokumukeirekisho-ai-chatgpt-sakusei/は「作り方・プロンプト例」に特化し、タイトルから「バレる」を外す。本記事は履歴書・職務経歴書の両方の「バレる？」を担当し、職務経歴書の見出しを強化。「チャッピー」など俗称（33表示）も本文で拾う。 | Y11: 【案A】履歴書・職務経歴書のAI作成はバレる？採用担当が答える「バレる文章」の特徴 【案B】【人事が回答】AIで書いた職務経歴書はバレる？バレても落ちない使い方 【説明文】結論、AIで作った履歴書・職務経歴書は「使い方次第でバレます」。現役の採用担当が、AI文章だと気づく瞬間と、バレても評価が下がらない使い方を具体例つきで解説。 | Z11: ①「バレても落ちない使い方」の末尾：「AIの下書きは、採用側の目線を持つ第三者に一度見てもらうのが確実。エージェントの書類添削は無料なので、下書きを持ち込むのが一番コスパが良い」→リクルートエージェント ②「人事が見ているポイント」：「ITエンジニアなら、職務経歴書を登録してスカウトが来るかで書類の通過力を試せる」→レバテックダイレクト | AA11: リクルートエージェント(VC) | AB11: 中 | AC11: 個別に判断
A12: 8 | B12: S | C12: 今週〜2週間 | D12: /instant-offer-one-interview-black-company-warning/ | E12: 求人票・ブラック企業 | F12: 即内定 | G12: 9968 | H12: 349 | I12: =IFERROR(H12/G12,0) -> 0.035012039 | J12: 6.3 | K12: 6 | L12: 4.55 | M12: 2.07 | N12: 下落 | O12: =M12*30 -> 62.1 | P12: 89.4 | Q12: 0.0232 | R12: =IF(K12="",0,INDEX(目次・前提!$B$35:$B$54,MIN(20,MAX(1,ROUND(K12,0))))) -> 0.06 | S12: =MAX(0,P12*30*(R12-Q12)) -> 98.6976 | T12: 面接1回で内定 やばい（764表示・2.8位・CTR7.6%） / 面接1回 やばい（393表示・2.5位・CTR9.7%） / 即日内定 やばい（308表示・5.5位・CTR2.6%） | U12: 日次クリック4.5→2.1に半減。順位は6.4→6.0でむしろ改善、表示−23%、CTRが3.9%→2.3%に低下。順位ではなく検索結果の見え方（競合タイトル・AIによる概要表示など）の変化が原因の可能性が高い。主要クエリ「面接1回で内定 やばい」764表示2.8位CTR7.6%は健在。 | V12: 小 | W12: 【即内定】競合相手：/low-hiring-standards-black-company-risk/ | X12: まずシークレットウィンドウで「面接1回で内定 やばい」「即日内定 やばい」の検索結果を目視確認。「即日内定 やばい」308表示5.5位CTR2.6%、「1day選考会 やばい」（計175表示・22〜24位）に答える見出しを追加。「面接1回 ホワイト」（208表示3.1位）向けに「ホワイトな場合」の見出しを強化。/low-hiring-standards-black-company-risk/と相互リンク。 | Y12: 【案A】面接1回で内定はやばい？人事が教える「ブラックかどうか」見分ける5つの質問 【案B】面接1回・即日内定はやばい？ホワイト企業との違いを現役人事が解説 【説明文】面接1回で内定が出るのは危ないのか、現役の採用担当が理由を解説。即内定でもホワイトな企業の特徴と、内定承諾前に確認すべき質問を具体的に。 | Z12: 読者は内定を持って迷っている、緊急度の高い層。 ①「内定承諾前に確認すべきこと」：「承諾の返事をする前に、退職者の口コミを5分だけ見て。転職会議なら面接内容や入社後のギャップの口コミがまとまっている」→転職会議 ②記事末：「1社だけで決めるのが不安なら、エージェント経由で比較対象の内定を持っておくと判断を誤らない」→リクルートエージェント | AA12: 転職会議(VC)/リクルートエージェント(VC) | AB12: 小 | AC12: 個別に判断
A13: 9 | B13: S | C13: 今週〜2週間 | D13: /it-tensyoku-agent-osusume/ | E13: 転職サービス評判 | F13: エージェント総合 | G13: 72 | H13: 0 | I13: =IFERROR(H13/G13,0) -> 0 | J13: 11.9 | K13: 10.1 | L13: 0 | M13: 0 | N13: 横ばい | O13: =M13*30 -> 0 | P13: 1.9 | Q13: 0 | R13: =IF(K13="",0,INDEX(目次・前提!$B$35:$B$54,MIN(20,MAX(1,ROUND(K13,0))))) -> 0.035 | S13: =MAX(0,P13*30*(R13-Q13)) -> 1.995 | T13: （上位1,000件のクエリに該当なし） | U13: 3か月72表示・11.9位・クリック0。「IT転職エージェント おすすめ」は大手メディアが占めるビッグワードで、短期の上位化は現実的でない。一方で「企業側から見て質の高いエージェント」という切り口はサイトで最も強い一次情報。現行タイトル（検索結果で確認）は長すぎて切れる。 | V13: 中 | W13: 【エージェント総合】競合相手：/agent-review/ | X13: 検索流入ではなく「サイト内からの送客で稼ぐ収益ハブ」に位置付け直す。エージェント個別評判記事（14本）と相互リンク（ハブ＆スポーク）。/agent-review/（表示1回）を本記事に統合。KPIは順位ではなく「サイト内からの流入 月100以上」。 | Y13: 【案】IT転職エージェントおすすめ8社｜企業側の人事が「本当に使える」と思う会社 【説明文】求人を出す側の現役IT人事が、候補者の質・提案力から本当に使える転職エージェント8社を厳選。年収・経験年数別にどこへ登録すべきかを本音で解説。 | Z13: ①冒頭に「タイプ別おすすめ早見表」の3択：とりあえず1社→リクルートエージェント／年収600万円以上→JAC／ITエンジニアでスカウト型→レバテックダイレクト ②各社紹介の末尾に「企業側から見た評価」の一言＋ボタン ③「併用のすすめ」：「エージェントごとに求人が違うので2社併用が基本」 ※掲載8社は提携済み案件（VC：リクルートエージェント・JAC、A8：レバテックダイレクト・Geekly・第二新卒エージェントneo）を優先 | AA13: リクルートエージェント(VC)/JAC(VC)/レバテックダイレクト(A8) | AB13: 中 | AC13: 個別に判断
A14: 10 | B14: A | C14: 今月中 | D14: /tenshokukaigi-cancel-withdrawal/ | E14: 口コミサイト活用 | F14: 転職会議 | G14: 3716 | H14: 263 | I14: =IFERROR(H14/G14,0) -> 0.070775027 | J14: 4.5 | K14: 4.5 | L14: 1.2 | M14: 6.64 | N14: 急伸 | O14: =M14*30 -> 199.2 | P14: 86 | Q14: 0.0772 | R14: =IF(K14="",0,INDEX(目次・前提!$B$35:$B$54,MIN(20,MAX(1,ROUND(K14,0))))) -> 0.08 | S14: =MAX(0,P14*30*(R14-Q14)) -> 7.224 | T14: 転職会議 退会（1,169表示・5.3位・CTR3.7%） / 転職会議 解約（530表示・6.0位・CTR2.6%） / 転職会議 有料 解約（279表示・4.6位・CTR3.9%） | U14: 4.5位・CTR7.1%で健全、日次クリック1.2→6.6に増加。「転職会議 退会」1,169表示5.3位、「解約」530表示6.0位。 | V14: 強 | W14: 【転職会議】競合相手：/tenshokukaigi-kuchikomi-mikata-tsukaikata/、/tenshokukaigi-openwork-comparison/、/tenshokukaigi-toroku-bareru/ | X14: 手順の画像と所要時間を冒頭に置き3位以内を狙う。「livesense 解約」（49表示）など請求名での検索にも対応。 | Y14: 現行維持。説明文で「1分で完了・有料プランの解約手順も」を明示。 | Z14: 退会したい読者に転職会議は勧めない（信頼を損なう）。「口コミを見る目的だけなら有料プランを解約して無料会員に戻す選択肢も」と案内し、OpenWork記事へ内部リンク。 | AA14: 転職会議(VC) | AB14: 小 | AC14: 個別に判断
A15: 11 | B15: A | C15: 今月中 | D15: /openwork-toroku-bareru/ | E15: 口コミサイト活用 | F15: OpenWork | G15: 2844 | H15: 94 | I15: =IFERROR(H15/G15,0) -> 0.033052039 | J15: 5.8 | K15: 5.8 | L15: 0.05 | M15: 3.25 | N15: 新規出現 | O15: =M15*30 -> 97.5 | P15: 99.7 | Q15: 0.0326 | R15: =IF(K15="",0,INDEX(目次・前提!$B$35:$B$54,MIN(20,MAX(1,ROUND(K15,0))))) -> 0.06 | S15: =MAX(0,P15*30*(R15-Q15)) -> 81.9534 | T15: オープンワーク 登録 ばれる（2,285表示・7.0位・CTR1.5%） / openwork バレる（422表示・7.1位・CTR0.7%） / オープンワーク 登録 バレる（241表示・6.3位・CTR0.0%） | U15: 直近28日で表示/日が約1→100に急伸（新しい記事）。「オープンワーク 登録 ばれる」2,285表示7.0位CTR1.5%、「openwork バレる」422表示7.1位。/openwork-tsukaikata/とバレる系で競合している可能性。 | V15: 中 | W15: 【OpenWork】競合相手：/openwork-tsukaikata/、/openwork-graph-mikata/、/openwork-white-company-mikata/、/openwork-hikaku-kinou/ | X15: バレる系クエリの専任記事にする。tsukaikata側のバレる解説を縮小して本記事にリンクを集める。「企業ブロック」「Web履歴書 非公開」（計200表示超）の見出しを追加。冒頭で「結論：バレない設定の手順」を即答。 | Y15: 【案】OpenWorkの登録は会社にバレる？企業ブロックとWeb履歴書の非公開設定【現役人事】 | Z15: 「バレない設定」の直後：「身バレが不安なら、口コミの裏取りは転職会議でも可能」→転職会議 記事末：スカウトを受けたい人→レバテックダイレクト（非公開・ブロック機能の有無は公式で要確認） | AA15: 転職会議(VC) | AB15: 小 | AC15: 個別に判断
A16: 12 | B16: A | C16: 今月中 | D16: /nec-career-change-reputation-difficulty/ | E16: IT企業研究 | F16: NEC | G16: 5236 | H16: 267 | I16: =IFERROR(H16/G16,0) -> 0.050993125 | J16: 5.8 | K16: 4.4 | L16: 2.14 | M16: 4.64 | N16: 急伸 | O16: =M16*30 -> 139.2 | P16: 59.1 | Q16: 0.0786 | R16: =IF(K16="",0,INDEX(目次・前提!$B$35:$B$54,MIN(20,MAX(1,ROUND(K16,0))))) -> 0.1 | S16: =MAX(0,P16*30*(R16-Q16)) -> 37.9422 | T16: nec 退職金（368表示・5.3位・CTR10.9%） / nec 退職金 いくら（176表示・3.2位・CTR9.1%） / nec退職金いくら（142表示・2.9位・CTR12.0%） | U16: 5.8位・CTR5.1%、日次クリック2.1→4.6。関連クエリは「nec 退職金」368表示5.3位CTR11%、「nec 早期退職 2026」118表示3.8位など、退職金・早期退職が中心。読者はNEC社員で、転職を検討し始めた層（収益化の見込みが高い）。 | V16: なし | W16: 同じ意図の記事なし | X16: 退職金・早期退職・リストラ（計700表示超）の見出しを強化し、退職金の計算例を追加。「日本電気 退職金」（98表示5.4位）など正式社名でも拾う。 | Y16: 【案】NECの退職金はいくら？早期退職・転職の難易度と評判を現役IT人事が解説 （現行タイトルに「退職金」が入っていなければ必ず入れる） | Z16: ①退職金・早期退職の見出しの直後：「早期退職に応じるか迷ったら、まず自分の市場価値を確認。応じる前に内定を持つのが鉄則」→JAC Recruitment／レバテックダイレクト ②記事末：社内でバレずに情報収集できるスカウト型を紹介 | AA16: JAC Recruitment(VC)/リクルートエージェント(VC) | AB16: 中 | AC16: 個別に判断
... A42: 38 | B42: B | C42: 来月 | D42: /itpassport-kihonjoho-2027-henkou/ | E42: IPA試験・IT資格 | F42: ITパスポート・基本情報 | G42: 1857 | H42: 95 | I42: =IFERROR(H42/G42,0) -> 0.051157781 | J42: 7 | K42: 6.8 | L42: 0.62 | M42: 1.96 | N42: 急伸 | O42: =M42*30 -> 58.8 | P42: 36.3 | Q42: 0.0541 | R42: =IF(K42="",0,INDEX(目次・前提!$B$35:$B$54,MIN(20,MAX(1,ROUND(K42,0))))) -> 0.05 | S42: =MAX(0,P42*30*(R42-Q42)) -> 0 | T42: 基本情報 2027年（67表示・6.3位・CTR13.4%） / 基本情報技術者試験 2027 変更点（67表示・10.9位・CTR3.0%） / itパスポート 2027年 難しくなる（64表示・5.4位・CTR4.7%） | U42: 7.0位・CTR5.1%で水準並み以上。直近28日で急伸（クリック/日 0.6→2.0、表示/日 13→36）。取りこぼしクエリ：基本情報技術者試験 2027 変更点（67表示・10.9位）。 | V42: 中 | W42: 【ITパスポート・基本情報】競合相手：/it-passport-iminai/、/it-passport-kihonjoho-ukaranai/、/it-passport-kihonjoho-ikashikata/ | X42: 【差別化して残す】担当：2027年の制度変更だけを担当。親記事（/it-passport-iminai/）と重複する説明は3行要約＋リンクに置き換える。 順位は1ページ目。本文は大きく変えず、「基本情報技術者試験 2027 変更点」向けの見出し追加と導線の設置に留める。 | Y42: 大きな変更は不要。タイトルに「基本情報 2027年」が入っていなければ追加。 | Z42: 若手・未経験の読者が中心。記事末に「資格より先に、未経験でも応募できる求人を知っておくと勉強の優先順位が決まる」→第二新卒エージェントneo(A8)（ソフト導線）。 | AA42: 第二新卒エージェントneo(A8) | AB42: 中 | AC42: 自動診断
A43: 39 | B43: B | C43: 来月 | D43: /tensyoku-shorui-senkou-ochiru-riyuu/ | E43: 選考対策 | F43: 書類選考落ち | G43: 641 | H43: 9 | I43: =IFERROR(H43/G43,0) -> 0.014040562 | J43: 19.4 | L43: 0.14 | M43: 0 | N43: 直近28日は表示なし | O43: =M43*30 -> 0 | P43: 0 | Q43: 0 | R43: =IF(K43="",0,INDEX(目次・前提!$B$35:$B$54,MIN(20,MAX(1,ROUND(K43,0))))) -> 0 | S43: =MAX(0,P43*30*(R43-Q43)) -> 0 | T43: 書類選考 落ちる理由（39表示・28.9位・CTR0.0%） / 書類選考で落ちる人の履歴書・職務経歴書に共通する原因は何ですか？（29表示・21.2位・CTR0.0%） | U43: 平均19.4位で1ページ目の手前（あと一歩）。直近28日は検索結果に表示されていない（評価が他記事に移った可能性）。取りこぼしクエリ：書類選考 落ちる理由（39表示・28.9位）。 | V43: 強 | W43: 【書類選考落ち】競合相手：/chuto-syorui-senko-ochiru/、/it-tensyoku-syorui-ochiru-riyu/、/document-screening-cutoff/、/document-screening-pass-rate/、/document-screening-1minute/ほか | X43: 【統合対象】/chuto-syorui-senko-ochiru/へ統合し、本記事のURLは301リダイレクト。統合前に、本記事だけにある情報（数字・事例・人事の本音）を親記事へ移す。（グループ方針：chuto-syorui-senko-ochiruを親記事に。tensyoku-shorui-senkou-ochiru-riyuu・it-tensyoku-ochiru-kyotsu・document-screening-1minuteを親へ統合（301）。it-tensyoku-syorui-ochiru-riyu＝IT職特化、document-screening-cutoff＝足切り（年齢・学歴）、document-screening-pass-rate＝通過率データ、45sai＝40代、it-mikeiken＝未経験に差別化。） | Y43: -（統合するため不要） | Z43: 統合するため設置しない（統合先の記事で設置）。 | AA43: リクルートエージェント(VC) | AB43: 小 | AC43: 自動診断
A44: 40 | B44: B | C44: 来月 | D44: /geekly-hyouban/ | E44: 転職サービス評判 | F44: Geekly | G44: 567 | H44: 7 | I44: =IFERROR(H44/G44,0) -> 0.012345679 | J44: 17 | K44: 16.8 | L44: 0.09 | M44: 0.04 | N44: 表示急伸 | O44: =M44*30 -> 1.2 | P44: 9.5 | Q44: 0.0038 | R44: =IF(K44="",0,INDEX(目次・前提!$B$35:$B$54,MIN(20,MAX(1,ROUND(K44,0))))) -> 0.012 | S44: =MAX(0,P44*30*(R44-Q44)) -> 2.337 | T44: ギークリー 勝手 に 応募（186表示・17.9位・CTR0.0%） / ギークリー 勝手に応募（34表示・19.1位・CTR0.0%） / ギークリー 大量応募（11表示・17.1位・CTR9.1%） | U44: 17.0位。「ギークリー 勝手に応募」（計220表示）が17〜19位でクリック0。A8でGeekly提携済み（229表示・7クリック）なので収益に直結。 | V44: なし | W44: 同じ意図の記事なし | X44: 「勝手に応募される？」に冒頭で即答する見出しを追加（最大の検索需要）。 | Y44: 【案】ギークリーは勝手に応募される？評判と注意点を現役IT人事が解説 | Z44: 不安を解消した直後→Geeklyボタン「応募前に確認が入る設定で使う」（仕様は公式で要確認） | AA44: Geekly(A8) | AB44: 小 | AC44: 個別に判断
A45: 41 | B45: B | C45: 来月 | D45: /project-manager-exam-reform/ | E45: IPA試験・IT資格 | F45: 高度試験廃止 | G45: 1171 | H45: 166 | I45: =IFERROR(H45/G45,0) -> 0.14175918 | J45: 5.7 | K45: 5.2 | L45: 1.42 | M45: 2.68 | N45: 急伸 | O45: =M45*30 -> 80.4 | P45: 20.6 | Q45: 0.1302 | R45: =IF(K45="",0,INDEX(目次・前提!$B$35:$B$54,MIN(20,MAX(1,ROUND(K45,0))))) -> 0.08 | S45: =MAX(0,P45*30*(R45-Q45)) -> 0 | T45: プロジェクトマネージャー試験 意味ない（60表示・10.6位・CTR1.7%） / プロジェクトマネージャー試験（53表示・3.1位・CTR5.7%） / pm試験 2026（8表示・6.6位・CTR12.5%） | U45: 5.7位・CTR14.2%で水準並み以上。直近28日で急伸（クリック/日 1.4→2.7、表示/日 9→21）。取りこぼしクエリ：プロジェクトマネージャー試験 意味ない（60表示・10.6位）。 | V45: なし | W45: 【高度試験廃止】意図は分かれている | X45: 順位は1ページ目。本文は大きく変えず、「プロジェクトマネージャー試験 意味ない」向けの見出し追加と導線の設置に留める。 | Y45: 大きな変更は不要。タイトルに「プロジェクトマネージャー試験 意味ない」が入っていなければ追加。 | Z45: 転職意欲が低い読者のためソフト導線のみ。「資格は採用でどう評価されるか」の見出しに「経験の評価はスカウト型に職務経歴を登録すると分かる」→レバテックダイレクト。 | AA45: レバテックダイレクト(A8) | AB45: 中 | AC45: 自動診断
A46: 42 | B46: B | C46: 来月 | D46: /athome-kyujin-black-tensyoku/ | E46: 求人票・ブラック企業 | F46: 求人票の危険ワード | G46: 5278 | H46: 54 | I46: =IFERROR(H46/G46,0) -> 0.010231148 | J46: 8.2 | K46: 8.7 | L46: 0.7 | M46: 0.32 | N46: 下落 | O46: =M46*30 -> 9.6 | P46: 34.7 | Q46: 0.0093 | R46: =IF(K46="",0,INDEX(目次・前提!$B$35:$B$54,MIN(20,MAX(1,ROUND(K46,0))))) -> 0.04 | S46: =MAX(0,P46*30*(R46-Q46)) -> 31.9587 | T46: アット ホーム な職場 やばい（528表示・8.0位・CTR0.6%） / アットホームな職場です（363表示・8.4位・CTR1.7%） / アット ホーム 会社 やばい（238表示・9.7位・CTR0.0%） | U46: 3か月5,278表示・8.2位・CTR1.0%、日次クリック0.7→0.3に減少。「アットホームな職場 やばい」528表示8.0位CTR0.6%、「アットホームな職場です」363表示8.4位。 | V46: 小 | W46: 【求人票の危険ワード】競合相手：/annual-holidays-few-job-posting-warning/、/tairyo-boshu-kyujin-black-kigyo/、/kanbu-kouho-kyuujin-black/、/job-posting-high-salary-black-company-warning/、/kyuujinhyou-aimai-hyougen-black/ | X46: 冒頭で「アットホームな職場＝やばいとは限らない。危ない求人の見分け方」に即答。「なんj」的な本音系の検索にも答える率直なトーンに。 | Y46: 【案】「アットホームな職場です」はやばい？求人の本当の意味を採用担当が翻訳 | Z46: 「見分け方」の直後：「社風は求人票では分からない。口コミで残業・人間関係を確認」→転職会議 | AA46: 転職会議(VC) | AB46: 小 | AC46: 個別に判断
A47: 43 | B47: B | C47: 来月 | D47: /system-architect-haishi/ | E47: IPA試験・IT資格 | F47: 高度試験廃止 | G47: 2264 | H47: 186 | I47: =IFERROR(H47/G47,0) -> 0.082155477 | J47: 7.6 | K47: 7.5 | L47: 1.92 | M47: 2.25 | N47: 横ばい | O47: =M47*30 -> 67.5 | P47: 26 | Q47: 0.0867 | R47: =IF(K47="",0,INDEX(目次・前提!$B$35:$B$54,MIN(20,MAX(1,ROUND(K47,0))))) -> 0.045 | S47: =MAX(0,P47*30*(R47-Q47)) -> 0 | T47: システム アーキテク ト 試験 なくなる（144表示・2.3位・CTR13.9%） / システムアーキテクト試験（82表示・9.7位・CTR6.1%） / システム アーキテク ト 役に立た ない（77表示・9.5位・CTR7.8%） | U47: CTR8.2%。「システムアーキテクト試験 なくなる」は2.3位と好調だが、「システムアーキテクト試験」82表示9.7位、「役に立たない」77表示9.5位。 | V47: なし | W47: 【高度試験廃止】意図は分かれている | X47: 「役に立たない？」の見出しを追加。現行タイトル（検索結果で確認）は維持。 | Y47: 現行維持（「システムアーキテクトはなくなる？｜論述試験の行方と転職への影響を現役IT人事が解説」）。 | Z47: 「転職への影響」→レバテックダイレクト | AA47: レバテックダイレクト(A8) | AB47: 小 | AC47: 個別に判断
A48: 44 | B48: B | C48: 来月 | D48: /openwork-hikaku-kinou/ | E48: 口コミサイト活用 | F48: OpenWork | G48: 1141 | H48: 61 | I48: =IFERROR(H48/G48,0) -> 0.053461876 | J48: 7.7 | K48: 7.1 | L48: 0.83 | M48: 0.29 | N48: 下落 | O48: =M48*30 -> 8.7 | P48: 8.6 | Q48: 0.0333 | R48: =IF(K48="",0,INDEX(目次・前提!$B$35:$B$54,MIN(20,MAX(1,ROUND(K48,0))))) -> 0.05 | S48: =MAX(0,P48*30*(R48-Q48)) -> 4.3086 | T48: openwork 比較（70表示・2.4位・CTR18.6%） / オープンワーク 比較 やり方（52表示・1.6位・CTR21.1%） / オープンワーク 比較（52表示・4.1位・CTR1.9%） | U48: 7.7位・CTR5.3%で水準並み以上。クリックが下落（クリック/日 0.8→0.3）。取りこぼしクエリ：オープンワーク 比較（52表示・4.1位）。 | V48: 中 | W48: 【OpenWork】競合相手：/openwork-tsukaikata/、/openwork-graph-mikata/、/openwork-white-company-mikata/、/openwork-toroku-bareru/ | X48: 【差別化して残す】担当：比較機能の使い方だけを担当。伸びなければgraph-mikataへ統合。親記事（/openwork-tsukaikata/）と重複する説明は3行要約＋リンクに置き換える。 順位は1ページ目。本文は大きく変えず、「オープンワーク 比較」向けの見出し追加と導線の設置に留める。 | Y48: 大きな変更は不要。タイトルに「openwork 比較」が入っていなければ追加。 | Z48: 口コミの読み方・見分け方の見出しの末尾に、人事の本音ボックス「1サイトだけだと偏るので2サイトで裏取りを」→転職会議ボタン。 | AA48: 転職会議(VC) | AB48: 中 | AC48: 自動診断
A49: 45 | B49: B | C49: 来月 | D49: /aws-saa-difficulty/ | E49: IPA試験・IT資格 | F49: AWS資格 | G49: 3040 | H49: 83 | I49: =IFERROR(H49/G49,0) -> 0.027302632 | J49: 9.9 | K49: 8 | L49: 0.62 | M49: 1.54 | N49: 急伸 | O49: =M49*30 -> 46.2 | P49: 41.5 | Q49: 0.037 | R49: =IF(K49="",0,INDEX(目次・前提!$B$35:$B$54,MIN(20,MAX(1,ROUND(K49,0))))) -> 0.045 | S49: =MAX(0,P49*30*(R49-Q49)) -> 9.96 | T49: aws saa（146表示・11.1位・CTR0.7%） / saa 難易度 応用情報（134表示・4.6位・CTR7.5%） / aws 資格 年収（124表示・21.5位・CTR0.0%） | U49: 9.9位・CTR2.7%。「aws saa」146表示11.1位、「aws 資格 年収」124表示21.5位。「saa 難易度 応用情報」134表示4.6位CTR7%が強み。 | V49: 小 | W49: 【AWS資格】競合相手：/aws-sap-difficulty-salary/、/aws-cloud-practitioner-difficulty/ | X49: 「応用情報との難易度比較」を表で強化。「AWS資格と年収」の見出しを追加。SAAの難易度はこの記事に集約（LinuC記事と分担）。 | Y49: 現行（検索結果で確認：「AWS SAA（ソリューションアーキテクト アソシエイト）の難易度は？｜現役IT人事が解説」）に「応用情報と比較」を追加する案。 | Z49: 年収の見出し→レバテックダイレクト | AA49: レバテックダイレクト(A8) | AB49: 小 | AC49: 個別に判断
A50: 46 | B50: B | C50: 来月 | D50: /independent-sier-tier/ | E50: SIer・SES業界研究 | F50: 独立系SIer | G50: 280 | H50: 16 | I50: =IFERROR(H50/G50,0) -> 0.057142857 | J50: 10.3 | K50: 10.3 | L50: 0 | M50: 0.57 | N50: 新規出現 | O50: =M50*30 -> 17.1 | P50: 10 | Q50: 0.0571 | R50: =IF(K50="",0,INDEX(目次・前提!$B$35:$B$54,MIN(20,MAX(1,ROUND(K50,0))))) -> 0.035 | S50: =MAX(0,P50*30*(R50-Q50)) -> 0 | T50: （上位1,000件のクエリに該当なし） | U50: 平均10.3位で1ページ目の手前（あと一歩）。直近28日で新規出現（クリック/日 0.0→0.6、表示/日 0→10）。 | V50: 中 | W50: 【独立系SIer】競合相手：/independent-sier/、/independent-sier-delisting/ | X50: 【親記事（統合先）】担当：独立系SIerの一覧・Tier。統合する子記事の固有情報を取り込み、同グループの記事から内部リンクを集める。 1ページ目の手前。記事の主要キーワード（GSCで記事URLを絞り込んで表示クエリを確認）を含む見出しを追加して網羅性を補強し、同テーマの上位記事から内部リンクを追加して1ページ目入りを狙う。 | Y50: 順位の改善が先。タイトルの変更は後回し。 | Z50: 一覧表・ランキングの直後に「自分の経験でどのTierに入れるかはスカウトを受けると分かる」→レバテックダイレクト(A8)。 | AA50: レバテックダイレクト(A8) | AB50: 小 | AC50: 自動診断
A51: 47 | B51: B | C51: 来月 | D51: /assign-agent-review/ | E51: 転職サービス評判 | F51: アサイン | G51: 3192 | H51: 89 | I51: =IFERROR(H51/G51,0) -> 0.027882206 | J51: 9.9 | K51: 11.3 | L51: 0.89 | M51: 1.14 | N51: 横ばい | O51: =M51*30 -> 34.2 | P51: 43.5 | Q51: 0.0263 | R51: =IF(K51="",0,INDEX(目次・前提!$B$35:$B$54,MIN(20,MAX(1,ROUND(K51,0))))) -> 0.025 | S51: =MAX(0,P51*30*(R51-Q51)) -> 0 | T51: アサイン エンジニア 転職（80表示・19.7位・CTR0.0%） / アサイン キャリアプランシート（79表示・4.2位・CTR3.8%） / アサイン キャリア面談（78表示・8.5位・CTR0.0%） | U51: 3か月3,192表示、9.9位→28日11.3位に低下、CTR2.8%。「アサイン エンジニア 転職」80表示19.7位、「キャリア面談」78表示8.5位CTR0%。アサインのASP提携状況は未確認。 | V51: なし | W51: 同じ意図の記事なし | X51: 「キャリアプランシート」「キャリア面談」など利用者の具体的な疑問に答える見出しを強化。 | Y51: 【案】アサイン（ASSIGN）の評判は？キャリア面談の中身を現役IT人事が解説 | Z51: 提携可否を確認。不可ならハイクラス代替としてJACへ誘導 | AA51: 要提携確認(アサイン) | AB51: 中 | AC51: 個別に判断
A52: 48 | B52: B | C52: 来月 | D52: /ipa-exam-reform-career-impact/ | E52: IPA試験・IT資格 | F52: IPA改編 | G52: 916 | H52: 70 | I52: =IFERROR(H52/G52,0) -> 0.076419214 | J52: 8.9 | K52: 9.2 | L52: 0.84 | M52: 0.57 | N52: 下落 | O52: =M52*30 -> 17.1 | P52: 9.8 | Q52: 0.0582 | R52: =IF(K52="",0,INDEX(目次・前提!$B$35:$B$54,MIN(20,MAX(1,ROUND(K52,0))))) -> 0.04 | S52: =MAX(0,P52*30*(R52-Q52)) -> 0 | T52: （上位1,000件のクエリに該当なし） | U52: 8.9位・CTR7.6%で水準並み以上。クリックが下落（クリック/日 0.8→0.6）。 | V52: 中 | W52: 【IPA改編】競合相手：/ipa-exam-reform-2027/、/professional-digital-skill-exam/、/data-management-exam/ | X52: 【差別化して残す】担当：改編が転職・採用での評価に与える影響だけを担当。親記事（/ipa-exam-reform-2027/）と重複する説明は3行要約＋リンクに置き換える。 順位は1ページ目。本文は大きく変えず、導線の設置を優先。 | Y52: 大きな変更は不要。 | Z52: 転職意欲が低い読者のためソフト導線のみ。「資格は採用でどう評価されるか」の見出しに「経験の評価はスカウト型に職務経歴を登録すると分かる」→レバテックダイレクト。 | AA52: レバテックダイレクト(A8) | AB52: 中 | AC52: 自動診断
A53: 49 | B53: B | C53: 来月 | D53: /ctc-tenshoku-nannido/ | E53: IT企業研究 | F53: 中堅SIer企業 | G53: 389 | H53: 14 | I53: =IFERROR(H53/G53,0) -> 0.035989717 | J53: 8.5 | K53: 8.5 | L53: 0 | M53: 0.5 | N53: 新規出現 | O53: =M53*30 -> 15 | P53: 13.9 | Q53: 0.036 | R53: =IF(K53="",0,INDEX(目次・前提!$B$35:$B$54,MIN(20,MAX(1,ROUND(K53,0))))) -> 0.04 | S53: =MAX(0,P53*30*(R53-Q53)) -> 1.668 | T53: ctc 年収 高い なぜ（32表示・10.2位・CTR0.0%） / ctc 転職（5表示・13.8位・CTR20.0%） | U53: 8.5位・CTR3.6%で水準並み以上。直近28日で新規出現（クリック/日 0.0→0.5、表示/日 0→14）。取りこぼしクエリ：ctc 年収 高い なぜ（32表示・10.2位）。 | V53: なし | W53: 同じ意図の記事なし | X53: 順位は1ページ目。本文は大きく変えず、「ctc 年収 高い なぜ」向けの見出し追加と導線の設置に留める。 | Y53: 大きな変更は不要。タイトルに「ctc 年収 高い なぜ」が入っていなければ追加。 | Z53: 年収・難易度の表の直下に「中途の条件は応募経路と交渉で変わる。エージェント経由なら面接傾向と年収レンジを事前に聞ける」→リクルートエージェント(VC)。記事末に「入社後のギャップは口コミで確認」→転職会議。 | AA53: リクルートエージェント(VC) | AB53: 中 | AC53: 自動診断
A54: 50 | B54: B | C54: 来月 | D54: /kyujinhyo-black-kigyo-checklist/ | E54: 求人票・ブラック企業 | F54: 求人票の見方 | G54: 575 | H54: 11 | I54: =IFERROR(H54/G54,0) -> 0.019130435 | J54: 13 | K54: 9.6 | L54: 0.12 | M54: 0.11 | N54: 横ばい | O54: =M54*30 -> 3.3 | P54: 6.7 | Q54: 0.016 | R54: =IF(K54="",0,INDEX(目次・前提!$B$35:$B$54,MIN(20,MAX(1,ROUND(K54,0))))) -> 0.035 | S54: =MAX(0,P54*30*(R54-Q54)) -> 3.819 | T54: こんな求人票は要注意（97表示・10.4位・CTR3.1%） | U54: 平均13.0位で1ページ目の手前（あと一歩）。取りこぼしクエリ：こんな求人票は要注意（97表示・10.4位）。 | V54: 中 | W54: 【求人票の見方】競合相手：/kyujinho-mikata-point/ | X54: 【親記事（統合先）】担当：求人票の見方・ブラック企業チェックリスト（求人票系のハブ）。統合する子記事の固有情報を取り込み、同グループの記事から内部リンクを集める。 1ページ目の手前。「こんな求人票は要注意」を含む見出しを追加して網羅性を補強し、同テーマの上位記事から内部リンクを追加して1ページ目入りを狙う。 | Y54: 順位の改善が先。タイトルは「こんな求人票は要注意」を含む形に整える程度に。 | Z54: 「応募前の確認方法」の見出しで「求人票に書かれない実態は口コミで確認」→転職会議。記事末に「内部情報はエージェント経由で聞ける」→リクルートエージェント。 | AA54: 転職会議(VC) | AB54: 中 | AC54: 自動診断
A55: 51 | B55: B | C55: 来月 | D55: /ses-syoryu-toritekiho-tenshoku/ | E55: SIer・SES業界研究 | F55: SES | G55: 817 | H55: 11 | I55: =IFERROR(H55/G55,0) -> 0.013463892 | J55: 9.9 | K55: 10.9 | L55: 0.14 | M55: 0.07 | N55: 横ばい | O55: =M55*30 -> 2.1 | P55: 11.2 | Q55: 0.0064 | R55: =IF(K55="",0,INDEX(目次・前提!$B$35:$B$54,MIN(20,MAX(1,ROUND(K55,0))))) -> 0.025 | S55: =MAX(0,P55*30*(R55-Q55)) -> 6.2496 | T55: ses 見分け方（247表示・42.8位・CTR0.0%） / ses 正社員型派遣（25表示・10.8位・CTR0.0%） / 正社員型派遣 ses（11表示・10.1位・CTR9.1%） | U55: 9.9位でCTR1.3%（同順位の目標4%を大きく下回る）。タイトル・説明文が検索意図に合っていない可能性。取りこぼしクエリ：ses 正社員型派遣（25表示・10.8位）。 | V55: 中 | W55: 【SES】競合相手：/sier-ses-docchi/、/ses-kigyou-miwakekata-erabikata/、/seishain-haken-ses-chigai/ | X55: 【差別化して残す】担当：商流・取適法（下請法改正）だけを担当。親記事（/ses-kigyou-miwakekata-erabikata/）と重複する説明は3行要約＋リンクに置き換える。 順位は1ページ目。本文は大きく変えず、「ses 正社員型派遣」向けの見出し追加と導線の設置に留める。 | Y55: CTRが低い。タイトル先頭に「ses 見分け方」を入れ、疑問形のクエリには説明文の冒頭で答えを言い切る。「現役IT人事」の要素は残す。 | Z55: 一覧表・ランキングの直後に「自分の経験でどのTierに入れるかはスカウトを受けると分かる」→レバテックダイレクト(A8)。 | AA55: レバテックダイレクト(A8) | AB55: 中 | AC55: 自動診断
... A132: 128 | B132: D | C132: 様子見・対応不要 | D132: /tensyoku-kaisuu-ooi-furi/ | E132: 選考対策 | F132: 転職回数 | G132: 5 | H132: 0 | I132: =IFERROR(H132/G132,0) -> 0 | J132: 5.8 | K132: 9 | L132: 0 | M132: 0 | N132: 表示ほぼなし | O132: =M132*30 -> 0 | P132: 0.1 | Q132: 0 | R132: =IF(K132="",0,INDEX(目次・前提!$B$35:$B$54,MIN(20,MAX(1,ROUND(K132,0))))) -> 0.04 | S132: =MAX(0,P132*30*(R132-Q132)) -> 0.12 | T132: （上位1,000件のクエリに該当なし） | U132: 3か月の表示5回でほぼ評価されていない。検索需要が小さいか、同テーマの他記事に評価を取られている。 | V132: なし | W132: 同じ意図の記事なし | X132: 表示がほぼないため、①需要がない→内部リンク用として残す、②同テーマの記事に評価を取られている→統合、のどちらかを判断。追記は後回し。 | Y132: - | Z132: 表示がほぼないため導線の設置は後回し（統合・リライト後に設置）。 | AA132: リクルートエージェント(VC) | AB132: 小 | AC132: 自動診断
A133: 129 | B133: D | C133: 様子見・対応不要 | D133: /sier-tensyoku-jittai/ | E133: SIer・SES業界研究 | F133: SIer比較 | G133: 1 | H133: 0 | I133: =IFERROR(H133/G133,0) -> 0 | J133: 8 | L133: 0 | M133: 0 | N133: 表示ほぼなし | O133: =M133*30 -> 0 | P133: 0 | Q133: 0 | R133: =IF(K133="",0,INDEX(目次・前提!$B$35:$B$54,MIN(20,MAX(1,ROUND(K133,0))))) -> 0 | S133: =MAX(0,P133*30*(R133-Q133)) -> 0 | T133: （上位1,000件のクエリに該当なし） | U133: 3か月の表示1回でほぼ評価されていない。検索需要が小さいか、同テーマの他記事に評価を取られている。 | V133: 小 | W133: 【SIer比較】競合相手：/major-sier-6-comparison/、/sier-consul-webkei-chigai/ | X133: 表示がほぼないため、①需要がない→内部リンク用として残す、②同テーマの記事に評価を取られている→統合、のどちらかを判断。追記は後回し。 | Y133: - | Z133: 表示がほぼないため導線の設置は後回し（統合・リライト後に設置）。 | AA133: リクルートエージェント(VC) | AB133: 小 | AC133: 自動診断
A134: 130 | B134: D | C134: 様子見・対応不要 | D134: /otsuka-shokai-tenshoku-kitsui/ | E134: IT企業研究 | F134: 中堅SIer企業 | G134: 356 | H134: 4 | I134: =IFERROR(H134/G134,0) -> 0.011235955 | J134: 9.6 | L134: 0.06 | M134: 0 | N134: 直近28日は表示なし | O134: =M134*30 -> 0 | P134: 0 | Q134: 0 | R134: =IF(K134="",0,INDEX(目次・前提!$B$35:$B$54,MIN(20,MAX(1,ROUND(K134,0))))) -> 0 | S134: =MAX(0,P134*30*(R134-Q134)) -> 0 | T134: 大塚商会 転勤（68表示・9.2位・CTR0.0%） / 大塚商会 se 激務（26表示・6.2位・CTR3.9%） | U134: 9.6位でCTR1.1%（同順位の目標4%を大きく下回る）。タイトル・説明文が検索意図に合っていない可能性。直近28日は検索結果に表示されていない（評価が他記事に移った可能性）。取りこぼしクエリ：大塚商会 転勤（68表示・9.2位）。 | V134: なし | W134: 同じ意図の記事なし | X134: 順位は1ページ目。本文は大きく変えず、「大塚商会 転勤」向けの見出し追加と導線の設置に留める。 | Y134: CTRが低い。タイトル先頭に「大塚商会 転勤」を入れ、疑問形のクエリには説明文の冒頭で答えを言い切る。「現役IT人事」の要素は残す。 | Z134: 年収・難易度の表の直下に「中途の条件は応募経路と交渉で変わる。エージェント経由なら面接傾向と年収レンジを事前に聞ける」→リクルートエージェント(VC)。記事末に「入社後のギャップは口コミで確認」→転職会議。 | AA134: リクルートエージェント(VC) | AB134: 中 | AC134: 自動診断
A135: 131 | B135: C | C135: 3か月以内（統合・整理） | D135: /ai-buntai-rirekisho-syokumukerekisho/ | E135: 選考対策 | F135: AI応募書類 | G135: 4 | H135: 0 | I135: =IFERROR(H135/G135,0) -> 0 | J135: 5.8 | L135: 0 | M135: 0 | N135: 表示ほぼなし | O135: =M135*30 -> 0 | P135: 0 | Q135: 0 | R135: =IF(K135="",0,INDEX(目次・前提!$B$35:$B$54,MIN(20,MAX(1,ROUND(K135,0))))) -> 0 | S135: =MAX(0,P135*30*(R135-Q135)) -> 0 | T135: （上位1,000件のクエリに該当なし） | U135: 3か月の表示4回でほぼ評価されていない。検索需要が小さいか、同テーマの他記事に評価を取られている。 | V135: 強 | W135: 【AI応募書類】競合相手：/rirekisho-ai-bareru/、/shokumukeirekisho-ai-chatgpt-sakusei/、/ai-mensetsu-shorui-senko/ | X135: 【統合対象】/rirekisho-ai-bareru/へ統合し、本記事のURLは301リダイレクト。統合前に、本記事だけにある情報（数字・事例・人事の本音）を親記事へ移す。（グループ方針：ai-buntai（表示ほぼゼロ）をrirekisho-ai-bareruへ統合し301。shokumukeirekisho-ai-chatgpt-sakuseiは「作り方・プロンプト」に特化しタイトルから「バレる」を外す。ai-mensetsu-shorui-senkoは「AI面接・AI書類選考（企業側がAIを使う話）」に差別化。） | Y135: -（統合するため不要） | Z135: 統合するため設置しない（統合先の記事で設置）。 | AA135: リクルートエージェント(VC) | AB135: 小 | AC135: 自動診断
A136: 132 | B136: D | C136: 様子見・対応不要 | D136: /tensyoku-jikopr-kakikata-tsutaekata/ | E136: 選考対策 | F136: 自己PR | G136: 1 | H136: 0 | I136: =IFERROR(H136/G136,0) -> 0 | J136: 6 | L136: 0 | M136: 0 | N136: 表示ほぼなし | O136: =M136*30 -> 0 | P136: 0 | Q136: 0 | R136: =IF(K136="",0,INDEX(目次・前提!$B$35:$B$54,MIN(20,MAX(1,ROUND(K136,0))))) -> 0 | S136: =MAX(0,P136*30*(R136-Q136)) -> 0 | T136: （上位1,000件のクエリに該当なし） | U136: 3か月の表示1回でほぼ評価されていない。検索需要が小さいか、同テーマの他記事に評価を取られている。 | V136: なし | W136: 同じ意図の記事なし | X136: 表示がほぼないため、①需要がない→内部リンク用として残す、②同テーマの記事に評価を取られている→統合、のどちらかを判断。追記は後回し。 | Y136: - | Z136: 表示がほぼないため導線の設置は後回し（統合・リライト後に設置）。 | AA136: リクルートエージェント(VC) | AB136: 小 | AC136: 自動診断
A137: 133 | B137: D | C137: 様子見・対応不要 | D137: /tensyoku-mensetsu-gyakushitsumon/ | E137: 選考対策 | F137: 面接対策 | G137: 24 | H137: 1 | I137: =IFERROR(H137/G137,0) -> 0.041666667 | J137: 10.6 | L137: 0.02 | M137: 0 | N137: 表示ほぼなし | O137: =M137*30 -> 0 | P137: 0 | Q137: 0 | R137: =IF(K137="",0,INDEX(目次・前提!$B$35:$B$54,MIN(20,MAX(1,ROUND(K137,0))))) -> 0 | S137: =MAX(0,P137*30*(R137-Q137)) -> 0 | T137: （上位1,000件のクエリに該当なし） | U137: 3か月の表示24回でほぼ評価されていない。検索需要が小さいか、同テーマの他記事に評価を取られている。 | V137: 中 | W137: 【面接対策】競合相手：/2ji-mensetsu-taisaku-tensyoku-mikeiken/、/it-tensyoku-mikeiken-1ji-mensetsu/、/it-tensyoku-saishu-mensetsu-taisaku/、/it-interview-points/、/online-interview-tips-from-it-hr/ | X137: 【差別化して残す】担当：逆質問として残し、ハブと相互リンク。親記事（/2ji-mensetsu-taisaku-tensyoku-mikeiken/）と重複する説明は3行要約＋リンクに置き換える。 表示がほぼないため、①需要がない→内部リンク用として残す、②同テーマの記事に評価を取られている→統合、のどちらかを判断。追記は後回し。 | Y137: - | Z137: 表示がほぼないため導線の設置は後回し（統合・リライト後に設置）。 | AA137: リクルートエージェント(VC) | AB137: 小 | AC137: 自動診断
A138: 134 | B138: C | C138: 3か月以内（統合・整理） | D138: /document-screening-pass-rate/ | E138: 選考対策 | F138: 書類選考落ち | G138: 53 | H138: 0 | I138: =IFERROR(H138/G138,0) -> 0 | J138: 11.6 | L138: 0 | M138: 0 | N138: 横ばい | O138: =M138*30 -> 0 | P138: 0 | Q138: 0 | R138: =IF(K138="",0,INDEX(目次・前提!$B$35:$B$54,MIN(20,MAX(1,ROUND(K138,0))))) -> 0 | S138: =MAX(0,P138*30*(R138-Q138)) -> 0 | T138: nttデータ 書類選考通過率 中途（117表示・7.1位・CTR8.6%） / nttデータ 書類選考 通過率 中途（79表示・9.7位・CTR2.5%） / nttデータ 中途採用 通過率（53表示・7.6位・CTR5.7%） | U138: 平均11.6位で1ページ目の手前（あと一歩）。取りこぼしクエリ：nttデータ 書類選考 通過率 中途（79表示・9.7位）。 | V138: 強 | W138: 【書類選考落ち】競合相手：/chuto-syorui-senko-ochiru/、/it-tensyoku-syorui-ochiru-riyu/、/tensyoku-shorui-senkou-ochiru-riyuu/、/document-screening-cutoff/、/document-screening-1minute/ほか | X138: 【差別化して残す】担当：書類選考の通過率データだけを担当（企業別の通過率は各企業記事へ）。親記事（/chuto-syorui-senko-ochiru/）と重複する説明は3行要約＋リンクに置き換える。 1ページ目の手前。「nttデータ 書類選考 通過率 中途」を含む見出しを追加して網羅性を補強し、同テーマの上位記事から内部リンクを追加して1ページ目入りを狙う。 | Y138: 順位の改善が先。タイトルは「nttデータ 書類選考通過率 中途」を含む形に整える程度に。 | Z138: 「自分で直すのが難しい人へ」の見出しで、エージェントの無料書類添削・面接対策を紹介→リクルートエージェント(VC)。 | AA138: リクルートエージェント(VC) | AB138: 小 | AC138: 自動診断
A139: 135 | B139: C | C139: 3か月以内（統合・整理） | D139: /it-tensyoku-ochiru-kyotsu/ | E139: 選考対策 | F139: 書類選考落ち | G139: 4 | H139: 0 | I139: =IFERROR(H139/G139,0) -> 0 | J139: 7.5 | L139: 0 | M139: 0 | N139: 表示ほぼなし | O139: =M139*30 -> 0 | P139: 0 | Q139: 0 | R139: =IF(K139="",0,INDEX(目次・前提!$B$35:$B$54,MIN(20,MAX(1,ROUND(K139,0))))) -> 0 | S139: =MAX(0,P139*30*(R139-Q139)) -> 0 | T139: 書類選考で落ちる人の履歴書・職務経歴書に共通する原因は何ですか？（29表示・21.2位・CTR0.0%） | U139: 3か月の表示4回でほぼ評価されていない。検索需要が小さいか、同テーマの他記事に評価を取られている。 | V139: 強 | W139: 【書類選考落ち】競合相手：/chuto-syorui-senko-ochiru/、/it-tensyoku-syorui-ochiru-riyu/、/tensyoku-shorui-senkou-ochiru-riyuu/、/document-screening-cutoff/、/document-screening-pass-rate/ほか | X139: 【統合対象】/chuto-syorui-senko-ochiru/へ統合し、本記事のURLは301リダイレクト。統合前に、本記事だけにある情報（数字・事例・人事の本音）を親記事へ移す。（グループ方針：chuto-syorui-senko-ochiruを親記事に。tensyoku-shorui-senkou-ochiru-riyuu・it-tensyoku-ochiru-kyotsu・document-screening-1minuteを親へ統合（301）。it-tensyoku-syorui-ochiru-riyu＝IT職特化、document-screening-cutoff＝足切り（年齢・学歴）、document-screening-pass-rate＝通過率データ、45sai＝40代、it-mikeiken＝未経験に差別化。） | Y139: -（統合するため不要） | Z139: 統合するため設置しない（統合先の記事で設置）。 | AA139: リクルートエージェント(VC) | AB139: 小 | AC139: 自動診断
A140: 136 | B140: D | C140: 様子見・対応不要 | D140: /uzuz-hyouban-jinji/ | E140: 転職サービス評判 | F140: UZUZ | G140: 1 | H140: 0 | I140: =IFERROR(H140/G140,0) -> 0 | J140: 7 | L140: 0 | M140: 0 | N140: 表示ほぼなし | O140: =M140*30 -> 0 | P140: 0 | Q140: 0 | R140: =IF(K140="",0,INDEX(目次・前提!$B$35:$B$54,MIN(20,MAX(1,ROUND(K140,0))))) -> 0 | S140: =MAX(0,P140*30*(R140-Q140)) -> 0 | T140: （上位1,000件のクエリに該当なし） | U140: 3か月の表示1回でほぼ評価されていない。検索需要が小さいか、同テーマの他記事に評価を取られている。 | V140: なし | W140: 同じ意図の記事なし | X140: 表示がほぼないため、①需要がない→内部リンク用として残す、②同テーマの記事に評価を取られている→統合、のどちらかを判断。追記は後回し。 | Y140: - | Z140: 表示がほぼないため導線の設置は後回し（統合・リライト後に設置）。 | AA140: 要提携確認(UZUZ)/第二新卒エージェントneo(A8) | AB140: 小 | AC140: 自動診断
A141: 137 | B141: C | C141: 3か月以内（統合・整理） | D141: /engineer-touta-ikinokoru/ | E141: キャリア・働き方 | F141: AI時代のキャリア | G141: 24 | H141: 0 | I141: =IFERROR(H141/G141,0) -> 0 | J141: 5.7 | L141: 0 | M141: 0 | N141: 表示ほぼなし | O141: =M141*30 -> 0 | P141: 0 | Q141: 0 | R141: =IF(K141="",0,INDEX(目次・前提!$B$35:$B$54,MIN(20,MAX(1,ROUND(K141,0))))) -> 0 | S141: =MAX(0,P141*30*(R141-Q141)) -> 0 | T141: （上位1,000件のクエリに該当なし） | U141: 3か月の表示24回でほぼ評価されていない。検索需要が小さいか、同テーマの他記事に評価を取られている。 | V141: 中 | W141: 【AI時代のキャリア】競合相手：/engineer-ai-nakunaru/、/ai-jidai-engineer-skill/ | X141: 【統合対象】/engineer-ai-nakunaru/へ統合し、本記事のURLは301リダイレクト。統合前に、本記事だけにある情報（数字・事例・人事の本音）を親記事へ移す。（グループ方針：engineer-ai-nakunaruを親に、skill・touta-ikinokoruを統合または差別化。） | Y141: -（統合するため不要） | Z141: 統合するため設置しない（統合先の記事で設置）。 | AA141: レバテックダイレクト(A8) | AB141: 小 | AC141: 自動診断
...

Sheet 重点9記事_詳細
A1: 重点9記事のアクションプラン
A2: 記事ごとに「データ分析 → カニバリ → タイトル・説明文 → アフィリエイト導線」の順で記載
A4: 優先1 /tenshokukaigi-kuchikomi-mikata-tsukaikata/
A5: 対象URL | B5: https://saiyo-ura.com/tenshokukaigi-kuchikomi-mikata-tsukaikata/
A6: 主要指標 | B6: 3か月：表示15,283・クリック147・CTR1.0%・平均9.7位／直近28日：クリック/日1.9（以前1.5）・平均9.5位
A7: 現在のデータからの分析 | B7: 3か月15,283表示（転職会議系で最大）なのにCTR1.0%・9.7位。「転職会議」1,646表示9.6位CTR0.5%、「口コミ 見る方法」1,027表示9.5位、「危ない」581表示クリック0。転職会議はVCで成果発生実績（9/12・330円）がある唯一の案件で、サイトで最も収益に近い記事。
A8: カニバリの有無と解消案 | B8: 判定：強 【転職会議】競合相手：/tenshokukaigi-openwork-comparison/、/tenshokukaigi-cancel-withdrawal/、/tenshokukaigi-toroku-bareru/ 統合ではなく役割分担。kuchikomi-mikata-tsukaikata＝総合（見る方法・評判・危ない）、openwork-comparison＝比較のみ、toroku-bareru＝身バレのみ、cancel-withdrawal＝退会のみ。重複セクションは3行要約＋リンクに。 転職会議系の親記事に位置付け、「危ない？評判は？」「無料で見る裏ワザ」「登録せずに見る方法」の見出しを追加。比較・身バレ・退会の詳細は各専門記事に任せて3行要約＋リンク。冒頭に目的別リンク（比較／バレる／退会）。
A9: SEO（CTR）改善案：タイトル・説明文 | B9: 【案A】【人事が解説】転職会議の口コミを無料で見る方法｜危ない？評判も本音で 【案B】転職会議の口コミの見方｜無料で全部見る方法と「危ない」の真相【現役人事】 【説明文】転職会議の口コミを無料で見る方法を現役IT人事が画面付きで解説。「危ない」「登録するとバレる？」への答えと、採用側から見た口コミの正しい読み方、OpenWorkとの使い分けまで。
A10: アフィリエイト導線の改善案 | B10: ①冒頭の結論ボックス：ボタン「転職会議で気になる会社の口コミを見る（無料）」 ②手順1の中：テキストリンク「まずは公式ページで無料会員登録→」 ③「危ない？」の不安を解消した直後：「人事の立場から言うと、投稿者が特定されることはまずない」→ボタン ④記事末の人事の本音ボックス：「面接で口コミの話題を出す企業は多い。面接体験談まで読んだ候補者は準備の深さが違う」→ボタン ※ボタンは3か所まで。登録条件は公式の最新情報で要確認
A11: 推奨案件（ASP） | B11: 転職会議(VC)
A12: 関連クエリ（推定） | B12: 転職会議（1,646表示・9.6位・CTR0.5%） / 転職会議 口コミ 見る方法（1,027表示・9.5位・CTR0.6%） / 転職会議 危ない（581表示・7.9位・CTR0.0%）
A14: 優先2 /openwork-tsukaikata/
A15: 対象URL | B15: https://saiyo-ura.com/openwork-tsukaikata/
A16: 主要指標 | B16: 3か月：表示25,323・クリック1,004・CTR4.0%・平均6.5位／直近28日：クリック/日13.4（以前9.8）・平均6.0位
A17: 現在のデータからの分析 | B17: 3か月25,323表示でサイト最大。28日CTR5.7%（3か月4.0%から改善中）・6.0位。「openwork 口コミ 見るには」2,107表示4.0位CTR10%は取れているが、「オープンワーク 口コミ」340表示7.0位CTR0.3%、「〜見るには 学生」294表示8.1位を取りこぼし。月約400クリックあるのに、ASPの表示数から見て収益導線がほぼない。
A18: カニバリの有無と解消案 | B18: 判定：中 【OpenWork】競合相手：/openwork-graph-mikata/、/openwork-white-company-mikata/、/openwork-toroku-bareru/、/openwork-hikaku-kinou/ tsukaikata＝口コミを見る方法、graph-mikata＝グラフ・形・点数、white-company＝ホワイト企業の見分け方、toroku-bareru＝バレる・企業ブロック。tsukaikataのバレる解説を縮小しtoroku-bareruへリンク。hikaku-kinouは統合候補。 バレる解説は3行要約＋/openwork-toroku-bareru/へのリンクに縮小し、「口コミを見る方法（投稿・Web履歴書・学生）」「見れない時の対処」に集中。学生向け見出しを新設。「あてにならない」「サクラ」（計300表示超）に答える見出しを追加。
A19: SEO（CTR）改善案：タイトル・説明文 | B19: 【案A】OpenWorkの口コミを見るには？無料で見る3つの方法【現役人事が解説】 【案B】OpenWork（オープンワーク）の使い方｜口コミを無料で見る方法と見れない時の対処 【説明文】OpenWorkの口コミを無料で見る方法を現役IT人事が解説。口コミ投稿・Web履歴書・学生の場合の見方、「見れない」時の対処、登録で会社にバレるかまで。採用側が実際に見ているポイントも紹介。
A20: アフィリエイト導線の改善案 | B20: ①「口コミが見れない時の対処」：OpenWorkで投稿したくない人向けの代替として転職会議（テキストリンク。閲覧条件は公式で要確認） ②「口コミの正しい読み方」の末尾に人事の本音ボックス：「口コミは辞めた人ほど書くので1サイトだと偏る。私は他社を調べる時、2サイトで同じ傾向が出るか必ず確認する」→ボタン「転職会議で同じ会社の口コミを見比べる（無料）」 ③記事末：「部署ごとの実態はエージェントに聞くのが早い」→/it-tensyoku-agent-osusume/
A21: 推奨案件（ASP） | B21: 転職会議(VC)
A22: 関連クエリ（推定） | B22: openwork 口コミ 見るには（2,107表示・4.0位・CTR10.0%） / オープンワーク 口コミ 見るには（861表示・3.5位・CTR9.5%） / オープンワーク 見方（419表示・1.1位・CTR49.2%）
A24: 優先3 /openwork-graph-mikata/
A25: 対象URL | B25: https://saiyo-ura.com/openwork-graph-mikata/
A26: 主要指標 | B26: 3か月：表示15,454・クリック2,754・CTR17.8%・平均4.5位／直近28日：クリック/日27.3（以前31.1）・平均4.4位
A27: 現在のデータからの分析 | B27: 月約820クリック・4.4位・CTR18.6%のサイト最大の稼ぎ頭（検索流入の約17%）。「オープンワーク 形」1,260表示1.8位など1〜2位を多数獲得し、SEOは完成度が高い。課題は収益導線だけ。この1記事が落ちるとサイト全体が約2割落ちる依存構造。
A28: カニバリの有無と解消案 | B28: 判定：中 【OpenWork】競合相手：/openwork-tsukaikata/、/openwork-white-company-mikata/、/openwork-toroku-bareru/、/openwork-hikaku-kinou/ tsukaikata＝口コミを見る方法、graph-mikata＝グラフ・形・点数、white-company＝ホワイト企業の見分け方、toroku-bareru＝バレる・企業ブロック。tsukaikataのバレる解説を縮小しtoroku-bareruへリンク。hikaku-kinouは統合候補。 本文の大幅リライトは禁止（順位を崩すリスク）。「ダイヤモンド型／逆ダイヤ型」（計260表示超・5〜6位）と「評価の目安・何点以上・平均点」（計550表示超）の小見出しを追加。目次見出しを検索語と同じ言葉にして、ジャンプリンク経由のクリックを増やす。
A29: SEO（CTR）改善案：タイトル・説明文 | B29: タイトルは原則変更しない（CTR18.6%は4位台として非常に高い）。説明文の末尾に「危険なグラフの形3パターンも図解」を追加する程度に留める。
A30: アフィリエイト導線の改善案 | B30: ①「要注意なグラフの形」の直後：「気になる形が出たら退職理由の口コミを確認。転職会議は退職理由の口コミが多い」→ボタン「転職会議でこの会社の退職理由を見る（無料）」 ②「人事はグラフをこう見る」の末尾：「応募前にエージェント経由で離職率・配属を確認する候補者は強い」→リクルートエージェント ③記事末：ボタンは1つだけ（選択肢を並べない） ※追加は計3か所まで
A31: 推奨案件（ASP） | B31: 転職会議(VC)/リクルートエージェント(VC)
A32: 関連クエリ（推定） | B32: オープンワーク 形（1,260表示・1.8位・CTR33.4%） / オープンワーク 見方（419表示・1.1位・CTR49.2%） / オープンワーク 評価 目安（387表示・4.6位・CTR8.3%）
A34: 優先4 /fujitsu-nenshu-hyouka-jinji-me/
A35: 対象URL | B35: https://saiyo-ura.com/fujitsu-nenshu-hyouka-jinji-me/
A36: 主要指標 | B36: 3か月：表示17,389・クリック906・CTR5.2%・平均6.8位／直近28日：クリック/日22.8（以前4.2）・平均5.8位
A37: 現在のデータからの分析 | B37: 日次クリック4.2→22.8に急伸し月約680クリック（2番目の柱）。等級・役職別クエリは4〜6位で強いが、親キーワード「富士通 年収」1,136表示は11.2位・CTR4.1%で1ページ目外。「富士通 40歳年収」「事業部長 年収」はクリック0。読者は社員（自分の等級確認）と転職検討者の2種類。
A38: カニバリの有無と解消案 | B38: 判定：なし 同じ意図の記事なし タイトル先頭を「富士通の年収」にして親キーワードを狙う。年齢別（30/35/40歳）の年収表と、事業部長・執行役員の行を追加。「富士通 給料」（49表示20.7位）「給与体系」もカバー。最終更新日を明記。
A39: SEO（CTR）改善案：タイトル・説明文 | B39: 【案A】富士通の年収はいくら？レベル別・役職別・年齢別の実態【現役IT人事】 【案B】富士通の年収をレベル9〜15・役職別に解説｜40歳・管理職の実額も 【説明文】富士通の年収をFJレベル（9〜15）・役職・年齢別に整理。ジョブ型人事制度で何が変わったか、中途入社で何レベルからスタートできるかを現役IT人事の目線で解説。
A40: アフィリエイト導線の改善案 | B40: 読者を2種類に分ける。 ①レベル別年収表の直下（転職検討者向け）：「中途で何レベルから始まるかはオファー前の交渉でほぼ決まる。ハイクラスに強いエージェント経由の候補者は交渉材料を持っていることが多い」→JAC Recruitment ②「ジョブ型・評価」の末尾（社員向け）：「今のレベルが市場でどう評価されるかはスカウトを受けるのが早い。登録だけなら社内にバレない」→レバテックダイレクト ③記事末：2択ボタン「富士通に転職したい人→」「富士通から転職を考えている人→」
A41: 推奨案件（ASP） | B41: JAC Recruitment(VC)/レバテックダイレクト(A8)
A42: 関連クエリ（推定） | B42: 富士通 年収（1,136表示・11.2位・CTR4.1%） / 富士通 シニアマネージャー 年収（348表示・5.7位・CTR6.0%） / 富士通 レベル（309表示・6.5位・CTR5.2%）
A44: 優先5 /recruit-agent-hyoban/
A45: 対象URL | B45: https://saiyo-ura.com/recruit-agent-hyoban/
...

Sheet カニバリ分析
A1: カニバリゼーション（記事同士の競合）分析
A2: 推定。確定は下の「GSCでの確認手順」で行ってください
A3: 競合グループ | B3: 判定 | C3: 記事数 | D3: 3か月表示（合計） | E3: 記事（表示・平均順位） | F3: 根拠 | G3: 解消案（統合・差別化） | H3: GSCで確認すべきクエリ
A4: 転職会議 | B4: 強 | C4: 4 | D4: 28561 | E4: /tenshokukaigi-kuchikomi-mikata-tsukaikata/（15,283表示・9.7位） /tenshokukaigi-openwork-comparison/（8,555表示・7.9位） /tenshokukaigi-cancel-withdrawal/（3,716表示・4.5位） /tenshokukaigi-toroku-bareru/（1,007表示・6.0位） | F4: 4記事が「転職会議」系クエリを分け合い、汎用クエリ「転職会議」1,646表示は9.6位・CTR0.5%、「口コミ 見る方法」1,027表示は9.5位。3記事とも6〜10位で頭打ち。 | G4: 統合ではなく役割分担。kuchikomi-mikata-tsukaikata＝総合（見る方法・評判・危ない）、openwork-comparison＝比較のみ、toroku-bareru＝身バレのみ、cancel-withdrawal＝退会のみ。重複セクションは3行要約＋リンクに。 | H4: 転職会議 / 転職会議 口コミ 見る方法 / 転職会議 評判 / 転職会議 登録
A5: リクルートエージェント | B5: 強 | C5: 2 | D5: 2891 | E5: /recruit-agent-hyoban/（2,082表示・5.4位） /recruit-agent-tsukaikata/（809表示・6.2位） | F5: 評判記事（hyoban）の関連クエリ上位が「面接後アンケート」系で、直近28日に公開された使い方記事（tsukaikata）も同じクエリに該当。本来の「評判」系クエリが上位1,000件に入っていない。 | G5: hyoban＝評判・口コミ・向いてる人（登録前の判断）、tsukaikata＝面接後アンケート・求人ポスト・面談（登録後の使い方）。hyoban側のアンケート詳細はtsukaikataへ移す。 | H5: リクルートエージェント 面接後 アンケート / リクルートエージェント 求人ポストとは / リクルートエージェント 評判
A6: AI応募書類 | B6: 強 | C6: 4 | D6: 3980 | E6: /rirekisho-ai-bareru/（3,319表示・7.5位） /shokumukeirekisho-ai-chatgpt-sakusei/（529表示・13.4位） /ai-mensetsu-shorui-senko/（128表示・8.1位） /ai-buntai-rirekisho-syokumukerekisho/（4表示・5.8位） | F6: AI×応募書類で4記事。主力のrirekisho-ai-bareruは7.5位→8.6位に低下し、「職務経歴書 ai バレる」は12.0位。 | G6: ai-buntai（表示ほぼゼロ）をrirekisho-ai-bareruへ統合し301。shokumukeirekisho-ai-chatgpt-sakuseiは「作り方・プロンプト」に特化しタイトルから「バレる」を外す。ai-mensetsu-shorui-senkoは「AI面接・AI書類選考（企業側がAIを使う話）」に差別化。 | H6: 履歴書 ai バレる / 職務経歴書 ai バレる / 職務経歴書 chatgpt バレる
A7: 書類選考落ち | B7: 強 | C7: 8 | D7: 3282 | E7: /chuto-syorui-senko-ochiru/（1,357表示・8.6位） /it-tensyoku-syorui-ochiru-riyu/（979表示・23.4位） /tensyoku-shorui-senkou-ochiru-riyuu/（641表示・19.4位） /document-screening-1minute/（99表示・7.9位） /45sai-it-shorui-senko/（86表示・22.5位） /document-screening-cutoff/（63表示・7.0位） /document-screening-pass-rate/（53表示・11.6位） /it-tensyoku-ochiru-kyotsu/（4表示・7.5位） | F7: 10記事が「書類選考で落ちる」意図を分け合い、代表クエリ「書類選考 落ちる」385表示は27.0位、「〜中途」255表示は20.5位、「〜理由」は28.9位。サイトで最も深刻な分散。 | G7: chuto-syorui-senko-ochiruを親記事に。tensyoku-shorui-senkou-ochiru-riyuu・it-tensyoku-ochiru-kyotsu・document-screening-1minuteを親へ統合（301）。it-tensyoku-syorui-ochiru-riyu＝IT職特化、document-screening-cutoff＝足切り（年齢・学歴）、document-screening-pass-rate＝通過率データ、45sai＝40代、it-mikeiken＝未経験に差別化。 | H7: 書類選考 落ちる / 書類選考 落ちる 中途 / 書類選考 落ちる理由 / 書類選考 通過率
A8: ユーザー系SIer | B8: 強 | C8: 2 | D8: 940 | E8: /user-sier-ranking/（547表示・20.2位） /user-sier-tier/（393表示・7.5位） | F8: 「ユーザー系sier一覧」7.5位と「ユーザー系sier 一覧」22.4位で表記揺れごとに順位が大きく割れ、ランキング記事は20.2位。tier記事とranking記事で評価が分散。 | G8: user-sier-rankingをuser-sier-tierへ統合（301）。tier記事に「ホワイト・人気ランキング」の見出しを追加。 | H8: ユーザー系sier 一覧 / ユーザー系sier ランキング
A9: 応募経路 | B9: 強 | C9: 2 | D9: 1084 | E9: /direct-application-vs-agent/（999表示・38.9位） /application-route-comparison/（85表示・8.8位） | F9: direct-application-vs-agent（38.9位・999表示・クリック2）とapplication-route-comparison（8.8位）が同じ「直接応募かエージェントか」の意図。「直接応募 どっち」系計500表示超が40〜54位。 | G9: 2記事を統合（評価の高いapplication-route-comparisonのURLを残し、もう一方を301）。 | H9: 転職エージェント 直接応募 どっち / 転職サイト 直接応募
A10: 企業研究のやり方 | B10: 強 | C10: 2 | D10: 242 | E10: /tensyoku-kigyou-kenkyuu/（171表示・11.7位） /tenshoku-kigyou-kenkyu-yarikata/（71表示・9.9位） | F10: tensyoku-kigyou-kenkyuuとtenshoku-kigyou-kenkyu-yarikataはスラッグもほぼ同じ重複記事。 | G10: 表示の多いtensyoku-kigyou-kenkyuuへ統合し301。 | H10: 転職 企業研究 やり方
A11: OpenWork | B11: 中 | C11: 5 | D11: 47912 | E11: /openwork-tsukaikata/（25,323表示・6.5位） /openwork-graph-mikata/（15,454表示・4.5位） /openwork-white-company-mikata/（3,150表示・7.4位） /openwork-toroku-bareru/（2,844表示・5.8位） /openwork-hikaku-kinou/（1,141表示・7.7位） | F11: 「オープンワーク 登録 ばれる」2,285表示が7.0位・CTR1.5%。専門記事（toroku-bareru）があるのに上位に行かず、総合記事（tsukaikata）とバレる系で評価が割れている可能性。「オープンワーク 見方」はtsukaikata・graph-mikataの双方の意図に該当。 | G11: tsukaikata＝口コミを見る方法、graph-mikata＝グラフ・形・点数、white-company＝ホワイト企業の見分け方、toroku-bareru＝バレる・企業ブロック。tsukaikataのバレる解説を縮小しtoroku-bareruへリンク。hikaku-kinouは統合候補。 | H11: オープンワーク 登録 ばれる / openwork バレる / オープンワーク 見方 / オープンワーク 評価 目安
A12: メーカー系SIer | B12: 中 | C12: 2 | D12: 462 | E12: /maker-sier-white-ranking/（326表示・24.5位） /maker-sier-tier/（136表示・9.2位） | F12: 「メーカー系sier一覧」64表示が29.3位、「メーカー系sier」44表示が41.9位。2記事とも順位が低い。 | G12: maker-sier-white-rankingをmaker-sier-tierへ統合（301）。 | H12: メーカー系sier 一覧 / メーカー系sier ホワイト
A13: 独立系SIer | B13: 中 | C13: 3 | D13: 531 | E13: /independent-sier-tier/（280表示・10.3位） /independent-sier/（166表示・9.8位） /independent-sier-delisting/（85表示・6.7位） | F13: independent-sier（9.8位）とindependent-sier-tier（10.3位）がほぼ同じ意図。 | G13: independent-sierをindependent-sier-tierへ統合（301）。上場廃止記事は別意図なので維持。 | H13: 独立系sier 一覧 / 独立系sier ランキング
A14: SES | B14: 中 | C14: 4 | D14: 1452 | E14: /ses-syoryu-toritekiho-tenshoku/（817表示・9.9位） /ses-kigyou-miwakekata-erabikata/（388表示・32.8位） /seishain-haken-ses-chigai/（191表示・15.5位） /sier-ses-docchi/（56表示・20.4位） | F14: 「ses 見分け方」247表示が42.8位でクリック0。ses-syoryu-toritekihoとses-kigyou-miwakekataの両方が該当。 | G14: ses-kigyou-miwakekataを「SES企業の見分け方」の親に。ses-syoryuは「商流・取適法」に特化。seishain-haken-ses-chigaiは「正社員型派遣との違い」に限定。 | H14: ses 見分け方 / ses 正社員型派遣
A15: IPA改編 | B15: 中 | C15: 4 | D15: 24161 | E15: /ipa-exam-reform-2027/（19,660表示・8.0位） /professional-digital-skill-exam/（3,251表示・7.1位） /ipa-exam-reform-career-impact/（916表示・8.9位） /data-management-exam/（334表示・8.6位） | F15: 改編の総合記事が「応用情報 なくなる」系を10位前後で受けている（受け皿記事の不足）。career-impactは関連クエリが上位1,000件に入らず、総合記事と意図が近い。 | G15: 応用情報の単独記事を新設（/ouyou-jouhou-haishi/ 仮）。総合記事は改編の全体像・試験別一覧のハブに。career-impactは「転職・採用での評価」に特化。 | H15: 応用情報技術者試験 なくなる / 情報処理技術者試験 2027
... A30: 高度試験廃止 | B30: なし | C30: 6 | D30: 18364 | E30: /network-specialist-haishi/（7,718表示・7.4位） /database-specialist-haishi/（3,394表示・8.9位） /it-strategist-haishi/（2,856表示・5.2位） /system-architect-haishi/（2,264表示・7.6位） /project-manager-exam-reform/（1,171表示・5.7位） /embedded-specialist-haishi/（961表示・12.7位） | F30: 試験ごとに記事が分かれ、主要クエリは1〜7位。DBスペシャリストCTR16%、ITストラテジスト19%と好調。 | G30: 現状の型を維持。応用情報だけ欠けているので追加。 | H30: -
A32: GSCでの確認手順（5分）
A33: 1. Search Console > 検索パフォーマンス > 「＋新規」>「検索キーワード」>「次と完全一致するキーワード」に上表のクエリを入力
A34: 2. 「ページ」タブを開き、2つ以上のURLに表示回数があればカニバリ確定
A35: 3. 期間を「過去3か月」にして比較をオンにすると、日によって表示URLが入れ替わっているかも分かる
A36: 4. 恒久的には GSC API で「クエリ×ページ」データを取得し、自動で判定する仕組みを作る（次の段階で対応可能）
A38: 参考：複数の記事の意図に該当するクエリ（表示上位40件・推定）
A39: クエリ | B39: 表示 | C39: クリック | D39: CTR | E39: 平均順位 | F39: 該当する記事
A40: オープンワーク 見方 | B40: 419 | C40: 206 | D40: =IFERROR(C40/B40,0) -> 0.49164678 | E40: 1.1 | F40: /openwork-tsukaikata/ /openwork-graph-mikata/
A41: ses 見分け方 | B41: 247 | C41: 0 | D41: =IFERROR(C41/B41,0) -> 0 | E41: 42.8 | F41: /ses-syoryu-toritekiho-tenshoku/ /ses-kigyou-miwakekata-erabikata/
A42: オープンワーク 口コミ 見方 | B42: 182 | C42: 23 | D42: =IFERROR(C42/B42,0) -> 0.12637363 | E42: 3.9 | F42: /openwork-tsukaikata/ /openwork-graph-mikata/
A43: saa 難易度 応用情報 | B43: 134 | C43: 10 | D43: =IFERROR(C43/B43,0) -> 0.074626866 | E43: 4.6 | F43: /ipa-exam-reform-2027/ /aws-saa-difficulty/
A44: nttデータ 書類選考通過率 中途 | B44: 117 | C44: 10 | D44: =IFERROR(C44/B44,0) -> 0.085470085 | E44: 7.1 | F44: /nttdata-chuto-nanido/ /document-screening-pass-rate/
A45: オープンワーク 形 ホワイト | B45: 104 | C45: 26 | D45: =IFERROR(C45/B45,0) -> 0.25 | E45: 2.1 | F45: /openwork-graph-mikata/ /openwork-white-company-mikata/
A46: openwork 見方 | B46: 97 | C46: 42 | D46: =IFERROR(C46/B46,0) -> 0.43298969 | E46: 2.3 | F46: /openwork-tsukaikata/ /openwork-graph-mikata/
A47: aws sap 難易度 応用情報 | B47: 89 | C47: 1 | D47: =IFERROR(C47/B47,0) -> 0.011235955 | E47: 8.8 | F47: /ipa-exam-reform-2027/ /aws-sap-difficulty-salary/
